Workbook

Sheet suma miesiaca
A1: Osoba | B1: L.Telefonow | C1: L. maili DWS | D1: L.Maili NTO | E1: L.Maili Vouchery | F1: L.Maili MDA | G1: L.TODO | H1: L.Chat | I1: Liczba NTO | J1: suma | K1: liczba ulotki | L1: suma rbh | M1: srednia zadan/godz
A2: Osoba 1 | B2: =SUM('01'!B2,'02'!B2,'03'!B2,'04'!B2,'05'!B2,'06'!B2,'07'!B2,'08'!B2,'09'!B2,'10'!B2,'11'!B2,'12'!B2,'13'!B2,'14'!B2,'15'!B2,'16'!B2,'17'!B2,'18'!B2,'19'!B2,'20'!B2,'21'!B2,'22'!B2,'23'!B2,'24'!B2,'25'!B2,'26'!B2,'27'!B2,'28'!B2,'29'!B2,'30'!B2,'31'!B2) -> 309 | C2: =SUM('01'!C2,'02'!C2,'03'!C2,'04'!C2,'05'!C2,'06'!C2,'07'!C2,'08'!C2,'09'!C2,'10'!C2,'11'!C2,'12'!C2,'13'!C2,'14'!C2,'15'!C2,'16'!C2,'17'!C2,'18'!C2,'19'!C2,'20'!C2,'21'!C2,'22'!C2,'23'!C2,'24'!C2,'25'!C2,'26'!C2,'27'!C2,'28'!C2,'29'!C2,'30'!C2,'31'!C2) -> 210 | D2: =SUM('01'!D2,'02'!D2,'03'!D2,'04'!D2,'05'!D2,'06'!D2,'07'!D2,'08'!D2,'09'!D2,'10'!D2,'11'!D2,'12'!D2,'13'!D2,'14'!D2,'15'!D2,'16'!D2,'17'!D2,'18'!D2,'19'!D2,'20'!D2,'21'!D2,'22'!D2,'23'!D2,'24'!D2,'25'!D2,'26'!D2,'27'!D2,'28'!D2,'29'!D2,'30'!D2,'31'!D2) -> 111 | E2: =SUM('01'!E2,'02'!E2,'03'!E2,'04'!E2,'05'!E2,'06'!E2,'07'!E2,'08'!E2,'09'!E2,'10'!E2,'11'!E2,'12'!E2,'13'!E2,'14'!E2,'15'!E2,'16'!E2,'17'!E2,'18'!E2,'19'!E2,'20'!E2,'21'!E2,'22'!E2,'23'!E2,'24'!E2,'25'!E2,'26'!E2,'27'!E2,'28'!E2,'29'!E2,'30'!E2,'31'!E2) -> 86 | F2: =SUM('01'!F2,'02'!F2,'03'!F2,'04'!F2,'05'!F2,'06'!F2,'07'!F2,'08'!F2,'09'!F2,'10'!F2,'11'!F2,'12'!F2,'13'!F2,'14'!F2,'15'!F2,'16'!F2,'17'!F2,'18'!F2,'19'!F2,'20'!F2,'21'!F2,'22'!F2,'23'!F2,'24'!F2,'25'!F2,'26'!F2,'27'!F2,'28'!F2,'29'!F2,'30'!F2,'31'!F2) -> 61 | G2: =SUM('01'!G2,'02'!G2,'03'!G2,'04'!G2,'05'!G2,'06'!G2,'07'!G2,'08'!G2,'09'!G2,'10'!G2,'11'!G2,'12'!G2,'13'!G2,'14'!G2,'15'!G2,'16'!G2,'17'!G2,'18'!G2,'19'!G2,'20'!G2,'21'!G2,'22'!G2,'23'!G2,'24'!G2,'25'!G2,'26'!G2,'27'!G2,'28'!G2,'29'!G2,'30'!G2,'31'!G2) -> 143 | H2: =SUM('01'!H2,'02'!H2,'03'!H2,'04'!H2,'05'!H2,'06'!H2,'07'!H2,'08'!H2,'09'!H2,'10'!H2,'11'!H2,'12'!H2,'13'!H2,'14'!H2,'15'!H2,'16'!H2,'17'!H2,'18'!H2,'19'!H2,'20'!H2,'21'!H2,'22'!H2,'23'!H2,'24'!H2,'25'!H2,'26'!H2,'27'!H2,'28'!H2,'29'!H2,'30'!H2,'31'!H2) -> 252 | I2: =SUM('01'!I2,'02'!I2,'03'!I2,'04'!I2,'05'!I2,'06'!I2,'07'!I2,'08'!I2,'09'!I2,'10'!I2,'11'!I2,'12'!I2,'13'!I2,'14'!I2,'15'!I2,'16'!I2,'17'!I2,'18'!I2,'19'!I2,'20'!I2,'21'!I2,'22'!I2,'23'!I2,'24'!I2,'25'!I2,'26'!I2,'27'!I2,'28'!I2,'29'!I2,'30'!I2,'31'!I2) -> 111 | J2: =SUM(B2:I2)+SUM(K2) -> 1360 | K2: 77 | L2: =SUM('01'!K2,'02'!K2,'03'!K2,'04'!K2,'05'!K2,'06'!K2,'07'!K2,'08'!K2,'09'!K2,'10'!K2,'11'!K2,'12'!K2,'13'!K2,'14'!K2,'15'!K2,'16'!K2,'17'!K2,'18'!K2,'19'!K2,'20'!K2,'21'!K2,'22'!K2,'23'!K2,'24'!K2,'25'!K2,'26'!K2,'27'!K2,'28'!K2,'29'!K2,'30'!K2,'31'!K2) -> 130 | M2: =IFERROR(J2/L2,"") -> 10.461538
A3: Osoba 2 | B3: =SUM('01'!B3,'02'!B3,'03'!B3,'04'!B3,'05'!B3,'06'!B3,'07'!B3,'08'!B3,'09'!B3,'10'!B3,'11'!B3,'12'!B3,'13'!B3,'14'!B3,'15'!B3,'16'!B3,'17'!B3,'18'!B3,'19'!B3,'20'!B3,'21'!B3,'22'!B3,'23'!B3,'24'!B3,'25'!B3,'26'!B3,'27'!B3,'28'!B3,'29'!B3,'30'!B3,'31'!B3) -> 213 | C3: =SUM('01'!C3,'02'!C3,'03'!C3,'04'!C3,'05'!C3,'06'!C3,'07'!C3,'08'!C3,'09'!C3,'10'!C3,'11'!C3,'12'!C3,'13'!C3,'14'!C3,'15'!C3,'16'!C3,'17'!C3,'18'!C3,'19'!C3,'20'!C3,'21'!C3,'22'!C3,'23'!C3,'24'!C3,'25'!C3,'26'!C3,'27'!C3,'28'!C3,'29'!C3,'30'!C3,'31'!C3) -> 167 | D3: =SUM('01'!D3,'02'!D3,'03'!D3,'04'!D3,'05'!D3,'06'!D3,'07'!D3,'08'!D3,'09'!D3,'10'!D3,'11'!D3,'12'!D3,'13'!D3,'14'!D3,'15'!D3,'16'!D3,'17'!D3,'18'!D3,'19'!D3,'20'!D3,'21'!D3,'22'!D3,'23'!D3,'24'!D3,'25'!D3,'26'!D3,'27'!D3,'28'!D3,'29'!D3,'30'!D3,'31'!D3) -> 95 | E3: =SUM('01'!E3,'02'!E3,'03'!E3,'04'!E3,'05'!E3,'06'!E3,'07'!E3,'08'!E3,'09'!E3,'10'!E3,'11'!E3,'12'!E3,'13'!E3,'14'!E3,'15'!E3,'16'!E3,'17'!E3,'18'!E3,'19'!E3,'20'!E3,'21'!E3,'22'!E3,'23'!E3,'24'!E3,'25'!E3,'26'!E3,'27'!E3,'28'!E3,'29'!E3,'30'!E3,'31'!E3) -> 80 | F3: =SUM('01'!F3,'02'!F3,'03'!F3,'04'!F3,'05'!F3,'06'!F3,'07'!F3,'08'!F3,'09'!F3,'10'!F3,'11'!F3,'12'!F3,'13'!F3,'14'!F3,'15'!F3,'16'!F3,'17'!F3,'18'!F3,'19'!F3,'20'!F3,'21'!F3,'22'!F3,'23'!F3,'24'!F3,'25'!F3,'26'!F3,'27'!F3,'28'!F3,'29'!F3,'30'!F3,'31'!F3) -> 75 | G3: =SUM('01'!G3,'02'!G3,'03'!G3,'04'!G3,'05'!G3,'06'!G3,'07'!G3,'08'!G3,'09'!G3,'10'!G3,'11'!G3,'12'!G3,'13'!G3,'14'!G3,'15'!G3,'16'!G3,'17'!G3,'18'!G3,'19'!G3,'20'!G3,'21'!G3,'22'!G3,'23'!G3,'24'!G3,'25'!G3,'26'!G3,'27'!G3,'28'!G3,'29'!G3,'30'!G3,'31'!G3) -> 124 | H3: =SUM('01'!H3,'02'!H3,'03'!H3,'04'!H3,'05'!H3,'06'!H3,'07'!H3,'08'!H3,'09'!H3,'10'!H3,'11'!H3,'12'!H3,'13'!H3,'14'!H3,'15'!H3,'16'!H3,'17'!H3,'18'!H3,'19'!H3,'20'!H3,'21'!H3,'22'!H3,'23'!H3,'24'!H3,'25'!H3,'26'!H3,'27'!H3,'28'!H3,'29'!H3,'30'!H3,'31'!H3) -> 188 | I3: =SUM('01'!I3,'02'!I3,'03'!I3,'04'!I3,'05'!I3,'06'!I3,'07'!I3,'08'!I3,'09'!I3,'10'!I3,'11'!I3,'12'!I3,'13'!I3,'14'!I3,'15'!I3,'16'!I3,'17'!I3,'18'!I3,'19'!I3,'20'!I3,'21'!I3,'22'!I3,'23'!I3,'24'!I3,'25'!I3,'26'!I3,'27'!I3,'28'!I3,'29'!I3,'30'!I3,'31'!I3) -> 85 | J3: =SUM(B3:I3)+SUM(K3) -> 1106 | K3: 79 | L3: =SUM('01'!K3,'02'!K3,'03'!K3,'04'!K3,'05'!K3,'06'!K3,'07'!K3,'08'!K3,'09'!K3,'10'!K3,'11'!K3,'12'!K3,'13'!K3,'14'!K3,'15'!K3,'16'!K3,'17'!K3,'18'!K3,'19'!K3,'20'!K3,'21'!K3,'22'!K3,'23'!K3,'24'!K3,'25'!K3,'26'!K3,'27'!K3,'28'!K3,'29'!K3,'30'!K3,'31'!K3) -> 122 | M3: =IFERROR(J3/L3,"") -> 9.0655738
A4: Osoba 3 | B4: =SUM('01'!B4,'02'!B4,'03'!B4,'04'!B4,'05'!B4,'06'!B4,'07'!B4,'08'!B4,'09'!B4,'10'!B4,'11'!B4,'12'!B4,'13'!B4,'14'!B4,'15'!B4,'16'!B4,'17'!B4,'18'!B4,'19'!B4,'20'!B4,'21'!B4,'22'!B4,'23'!B4,'24'!B4,'25'!B4,'26'!B4,'27'!B4,'28'!B4,'29'!B4,'30'!B4,'31'!B4) -> 294 | C4: =SUM('01'!C4,'02'!C4,'03'!C4,'04'!C4,'05'!C4,'06'!C4,'07'!C4,'08'!C4,'09'!C4,'10'!C4,'11'!C4,'12'!C4,'13'!C4,'14'!C4,'15'!C4,'16'!C4,'17'!C4,'18'!C4,'19'!C4,'20'!C4,'21'!C4,'22'!C4,'23'!C4,'24'!C4,'25'!C4,'26'!C4,'27'!C4,'28'!C4,'29'!C4,'30'!C4,'31'!C4) -> 155 | D4: =SUM('01'!D4,'02'!D4,'03'!D4,'04'!D4,'05'!D4,'06'!D4,'07'!D4,'08'!D4,'09'!D4,'10'!D4,'11'!D4,'12'!D4,'13'!D4,'14'!D4,'15'!D4,'16'!D4,'17'!D4,'18'!D4,'19'!D4,'20'!D4,'21'!D4,'22'!D4,'23'!D4,'24'!D4,'25'!D4,'26'!D4,'27'!D4,'28'!D4,'29'!D4,'30'!D4,'31'!D4) -> 117 | E4: =SUM('01'!E4,'02'!E4,'03'!E4,'04'!E4,'05'!E4,'06'!E4,'07'!E4,'08'!E4,'09'!E4,'10'!E4,'11'!E4,'12'!E4,'13'!E4,'14'!E4,'15'!E4,'16'!E4,'17'!E4,'18'!E4,'19'!E4,'20'!E4,'21'!E4,'22'!E4,'23'!E4,'24'!E4,'25'!E4,'26'!E4,'27'!E4,'28'!E4,'29'!E4,'30'!E4,'31'!E4) -> 105 | F4: =SUM('01'!F4,'02'!F4,'03'!F4,'04'!F4,'05'!F4,'06'!F4,'07'!F4,'08'!F4,'09'!F4,'10'!F4,'11'!F4,'12'!F4,'13'!F4,'14'!F4,'15'!F4,'16'!F4,'17'!F4,'18'!F4,'19'!F4,'20'!F4,'21'!F4,'22'!F4,'23'!F4,'24'!F4,'25'!F4,'26'!F4,'27'!F4,'28'!F4,'29'!F4,'30'!F4,'31'!F4) -> 90 | G4: =SUM('01'!G4,'02'!G4,'03'!G4,'04'!G4,'05'!G4,'06'!G4,'07'!G4,'08'!G4,'09'!G4,'10'!G4,'11'!G4,'12'!G4,'13'!G4,'14'!G4,'15'!G4,'16'!G4,'17'!G4,'18'!G4,'19'!G4,'20'!G4,'21'!G4,'22'!G4,'23'!G4,'24'!G4,'25'!G4,'26'!G4,'27'!G4,'28'!G4,'29'!G4,'30'!G4,'31'!G4) -> 132 | H4: =SUM('01'!H4,'02'!H4,'03'!H4,'04'!H4,'05'!H4,'06'!H4,'07'!H4,'08'!H4,'09'!H4,'10'!H4,'11'!H4,'12'!H4,'13'!H4,'14'!H4,'15'!H4,'16'!H4,'17'!H4,'18'!H4,'19'!H4,'20'!H4,'21'!H4,'22'!H4,'23'!H4,'24'!H4,'25'!H4,'26'!H4,'27'!H4,'28'!H4,'29'!H4,'30'!H4,'31'!H4) -> 234 | I4: =SUM('01'!I4,'02'!I4,'03'!I4,'04'!I4,'05'!I4,'06'!I4,'07'!I4,'08'!I4,'09'!I4,'10'!I4,'11'!I4,'12'!I4,'13'!I4,'14'!I4,'15'!I4,'16'!I4,'17'!I4,'18'!I4,'19'!I4,'20'!I4,'21'!I4,'22'!I4,'23'!I4,'24'!I4,'25'!I4,'26'!I4,'27'!I4,'28'!I4,'29'!I4,'30'!I4,'31'!I4) -> 98 | J4: =SUM(B4:I4)+SUM(K4) -> 1302 | K4: 77 | L4: =SUM('01'!K4,'02'!K4,'03'!K4,'04'!K4,'05'!K4,'06'!K4,'07'!K4,'08'!K4,'09'!K4,'10'!K4,'11'!K4,'12'!K4,'13'!K4,'14'!K4,'15'!K4,'16'!K4,'17'!K4,'18'!K4,'19'!K4,'20'!K4,'21'!K4,'22'!K4,'23'!K4,'24'!K4,'25'!K4,'26'!K4,'27'!K4,'28'!K4,'29'!K4,'30'!K4,'31'!K4) -> 144 | M4: =IFERROR(J4/L4,"") -> 9.0416667
A5: Osoba 4 | B5: =SUM('01'!B5,'02'!B5,'03'!B5,'04'!B5,'05'!B5,'06'!B5,'07'!B5,'08'!B5,'09'!B5,'10'!B5,'11'!B5,'12'!B5,'13'!B5,'14'!B5,'15'!B5,'16'!B5,'17'!B5,'18'!B5,'19'!B5,'20'!B5,'21'!B5,'22'!B5,'23'!B5,'24'!B5,'25'!B5,'26'!B5,'27'!B5,'28'!B5,'29'!B5,'30'!B5,'31'!B5) -> 289 | C5: =SUM('01'!C5,'02'!C5,'03'!C5,'04'!C5,'05'!C5,'06'!C5,'07'!C5,'08'!C5,'09'!C5,'10'!C5,'11'!C5,'12'!C5,'13'!C5,'14'!C5,'15'!C5,'16'!C5,'17'!C5,'18'!C5,'19'!C5,'20'!C5,'21'!C5,'22'!C5,'23'!C5,'24'!C5,'25'!C5,'26'!C5,'27'!C5,'28'!C5,'29'!C5,'30'!C5,'31'!C5) -> 148 | D5: =SUM('01'!D5,'02'!D5,'03'!D5,'04'!D5,'05'!D5,'06'!D5,'07'!D5,'08'!D5,'09'!D5,'10'!D5,'11'!D5,'12'!D5,'13'!D5,'14'!D5,'15'!D5,'16'!D5,'17'!D5,'18'!D5,'19'!D5,'20'!D5,'21'!D5,'22'!D5,'23'!D5,'24'!D5,'25'!D5,'26'!D5,'27'!D5,'28'!D5,'29'!D5,'30'!D5,'31'!D5) -> 95 | E5: =SUM('01'!E5,'02'!E5,'03'!E5,'04'!E5,'05'!E5,'06'!E5,'07'!E5,'08'!E5,'09'!E5,'10'!E5,'11'!E5,'12'!E5,'13'!E5,'14'!E5,'15'!E5,'16'!E5,'17'!E5,'18'!E5,'19'!E5,'20'!E5,'21'!E5,'22'!E5,'23'!E5,'24'!E5,'25'!E5,'26'!E5,'27'!E5,'28'!E5,'29'!E5,'30'!E5,'31'!E5) -> 73 | F5: =SUM('01'!F5,'02'!F5,'03'!F5,'04'!F5,'05'!F5,'06'!F5,'07'!F5,'08'!F5,'09'!F5,'10'!F5,'11'!F5,'12'!F5,'13'!F5,'14'!F5,'15'!F5,'16'!F5,'17'!F5,'18'!F5,'19'!F5,'20'!F5,'21'!F5,'22'!F5,'23'!F5,'24'!F5,'25'!F5,'26'!F5,'27'!F5,'28'!F5,'29'!F5,'30'!F5,'31'!F5) -> 91 | G5: =SUM('01'!G5,'02'!G5,'03'!G5,'04'!G5,'05'!G5,'06'!G5,'07'!G5,'08'!G5,'09'!G5,'10'!G5,'11'!G5,'12'!G5,'13'!G5,'14'!G5,'15'!G5,'16'!G5,'17'!G5,'18'!G5,'19'!G5,'20'!G5,'21'!G5,'22'!G5,'23'!G5,'24'!G5,'25'!G5,'26'!G5,'27'!G5,'28'!G5,'29'!G5,'30'!G5,'31'!G5) -> 99 | H5: =SUM('01'!H5,'02'!H5,'03'!H5,'04'!H5,'05'!H5,'06'!H5,'07'!H5,'08'!H5,'09'!H5,'10'!H5,'11'!H5,'12'!H5,'13'!H5,'14'!H5,'15'!H5,'16'!H5,'17'!H5,'18'!H5,'19'!H5,'20'!H5,'21'!H5,'22'!H5,'23'!H5,'24'!H5,'25'!H5,'26'!H5,'27'!H5,'28'!H5,'29'!H5,'30'!H5,'31'!H5) -> 235 | I5: =SUM('01'!I5,'02'!I5,'03'!I5,'04'!I5,'05'!I5,'06'!I5,'07'!I5,'08'!I5,'09'!I5,'10'!I5,'11'!I5,'12'!I5,'13'!I5,'14'!I5,'15'!I5,'16'!I5,'17'!I5,'18'!I5,'19'!I5,'20'!I5,'21'!I5,'22'!I5,'23'!I5,'24'!I5,'25'!I5,'26'!I5,'27'!I5,'28'!I5,'29'!I5,'30'!I5,'31'!I5) -> 85 | J5: =SUM(B5:I5)+SUM(K5) -> 1200 | K5: 85 | L5: =SUM('01'!K5,'02'!K5,'03'!K5,'04'!K5,'05'!K5,'06'!K5,'07'!K5,'08'!K5,'09'!K5,'10'!K5,'11'!K5,'12'!K5,'13'!K5,'14'!K5,'15'!K5,'16'!K5,'17'!K5,'18'!K5,'19'!K5,'20'!K5,'21'!K5,'22'!K5,'23'!K5,'24'!K5,'25'!K5,'26'!K5,'27'!K5,'28'!K5,'29'!K5,'30'!K5,'31'!K5) -> 118 | M5: =IFERROR(J5/L5,"") -> 10.169492
A6: Osoba 5 | B6: =SUM('01'!B6,'02'!B6,'03'!B6,'04'!B6,'05'!B6,'06'!B6,'07'!B6,'08'!B6,'09'!B6,'10'!B6,'11'!B6,'12'!B6,'13'!B6,'14'!B6,'15'!B6,'16'!B6,'17'!B6,'18'!B6,'19'!B6,'20'!B6,'21'!B6,'22'!B6,'23'!B6,'24'!B6,'25'!B6,'26'!B6,'27'!B6,'28'!B6,'29'!B6,'30'!B6,'31'!B6) -> 227 | C6: =SUM('01'!C6,'02'!C6,'03'!C6,'04'!C6,'05'!C6,'06'!C6,'07'!C6,'08'!C6,'09'!C6,'10'!C6,'11'!C6,'12'!C6,'13'!C6,'14'!C6,'15'!C6,'16'!C6,'17'!C6,'18'!C6,'19'!C6,'20'!C6,'21'!C6,'22'!C6,'23'!C6,'24'!C6,'25'!C6,'26'!C6,'27'!C6,'28'!C6,'29'!C6,'30'!C6,'31'!C6) -> 120 | D6: =SUM('01'!D6,'02'!D6,'03'!D6,'04'!D6,'05'!D6,'06'!D6,'07'!D6,'08'!D6,'09'!D6,'10'!D6,'11'!D6,'12'!D6,'13'!D6,'14'!D6,'15'!D6,'16'!D6,'17'!D6,'18'!D6,'19'!D6,'20'!D6,'21'!D6,'22'!D6,'23'!D6,'24'!D6,'25'!D6,'26'!D6,'27'!D6,'28'!D6,'29'!D6,'30'!D6,'31'!D6) -> 111 | E6: =SUM('01'!E6,'02'!E6,'03'!E6,'04'!E6,'05'!E6,'06'!E6,'07'!E6,'08'!E6,'09'!E6,'10'!E6,'11'!E6,'12'!E6,'13'!E6,'14'!E6,'15'!E6,'16'!E6,'17'!E6,'18'!E6,'19'!E6,'20'!E6,'21'!E6,'22'!E6,'23'!E6,'24'!E6,'25'!E6,'26'!E6,'27'!E6,'28'!E6,'29'!E6,'30'!E6,'31'!E6) -> 69 | F6: =SUM('01'!F6,'02'!F6,'03'!F6,'04'!F6,'05'!F6,'06'!F6,'07'!F6,'08'!F6,'09'!F6,'10'!F6,'11'!F6,'12'!F6,'13'!F6,'14'!F6,'15'!F6,'16'!F6,'17'!F6,'18'!F6,'19'!F6,'20'!F6,'21'!F6,'22'!F6,'23'!F6,'24'!F6,'25'!F6,'26'!F6,'27'!F6,'28'!F6,'29'!F6,'30'!F6,'31'!F6) -> 69 | G6: =SUM('01'!G6,'02'!G6,'03'!G6,'04'!G6,'05'!G6,'06'!G6,'07'!G6,'08'!G6,'09'!G6,'10'!G6,'11'!G6,'12'!G6,'13'!G6,'14'!G6,'15'!G6,'16'!G6,'17'!G6,'18'!G6,'19'!G6,'20'!G6,'21'!G6,'22'!G6,'23'!G6,'24'!G6,'25'!G6,'26'!G6,'27'!G6,'28'!G6,'29'!G6,'30'!G6,'31'!G6) -> 109 | H6: =SUM('01'!H6,'02'!H6,'03'!H6,'04'!H6,'05'!H6,'06'!H6,'07'!H6,'08'!H6,'09'!H6,'10'!H6,'11'!H6,'12'!H6,'13'!H6,'14'!H6,'15'!H6,'16'!H6,'17'!H6,'18'!H6,'19'!H6,'20'!H6,'21'!H6,'22'!H6,'23'!H6,'24'!H6,'25'!H6,'26'!H6,'27'!H6,'28'!H6,'29'!H6,'30'!H6,'31'!H6) -> 160 | I6: =SUM('01'!I6,'02'!I6,'03'!I6,'04'!I6,'05'!I6,'06'!I6,'07'!I6,'08'!I6,'09'!I6,'10'!I6,'11'!I6,'12'!I6,'13'!I6,'14'!I6,'15'!I6,'16'!I6,'17'!I6,'18'!I6,'19'!I6,'20'!I6,'21'!I6,'22'!I6,'23'!I6,'24'!I6,'25'!I6,'26'!I6,'27'!I6,'28'!I6,'29'!I6,'30'!I6,'31'!I6) -> 93 | J6: =SUM(B6:I6)+SUM(K6) -> 1002 | K6: 44 | L6: =SUM('01'!K6,'02'!K6,'03'!K6,'04'!K6,'05'!K6,'06'!K6,'07'!K6,'08'!K6,'09'!K6,'10'!K6,'11'!K6,'12'!K6,'13'!K6,'14'!K6,'15'!K6,'16'!K6,'17'!K6,'18'!K6,'19'!K6,'20'!K6,'21'!K6,'22'!K6,'23'!K6,'24'!K6,'25'!K6,'26'!K6,'27'!K6,'28'!K6,'29'!K6,'30'!K6,'31'!K6) -> 110 | M6: =IFERROR(J6/L6,"") -> 9.1090909
A7: Osoba 6 | B7: =SUM('01'!B7,'02'!B7,'03'!B7,'04'!B7,'05'!B7,'06'!B7,'07'!B7,'08'!B7,'09'!B7,'10'!B7,'11'!B7,'12'!B7,'13'!B7,'14'!B7,'15'!B7,'16'!B7,'17'!B7,'18'!B7,'19'!B7,'20'!B7,'21'!B7,'22'!B7,'23'!B7,'24'!B7,'25'!B7,'26'!B7,'27'!B7,'28'!B7,'29'!B7,'30'!B7,'31'!B7) -> 324 | C7: =SUM('01'!C7,'02'!C7,'03'!C7,'04'!C7,'05'!C7,'06'!C7,'07'!C7,'08'!C7,'09'!C7,'10'!C7,'11'!C7,'12'!C7,'13'!C7,'14'!C7,'15'!C7,'16'!C7,'17'!C7,'18'!C7,'19'!C7,'20'!C7,'21'!C7,'22'!C7,'23'!C7,'24'!C7,'25'!C7,'26'!C7,'27'!C7,'28'!C7,'29'!C7,'30'!C7,'31'!C7) -> 166 | D7: =SUM('01'!D7,'02'!D7,'03'!D7,'04'!D7,'05'!D7,'06'!D7,'07'!D7,'08'!D7,'09'!D7,'10'!D7,'11'!D7,'12'!D7,'13'!D7,'14'!D7,'15'!D7,'16'!D7,'17'!D7,'18'!D7,'19'!D7,'20'!D7,'21'!D7,'22'!D7,'23'!D7,'24'!D7,'25'!D7,'26'!D7,'27'!D7,'28'!D7,'29'!D7,'30'!D7,'31'!D7) -> 95 | E7: =SUM('01'!E7,'02'!E7,'03'!E7,'04'!E7,'05'!E7,'06'!E7,'07'!E7,'08'!E7,'09'!E7,'10'!E7,'11'!E7,'12'!E7,'13'!E7,'14'!E7,'15'!E7,'16'!E7,'17'!E7,'18'!E7,'19'!E7,'20'!E7,'21'!E7,'22'!E7,'23'!E7,'24'!E7,'25'!E7,'26'!E7,'27'!E7,'28'!E7,'29'!E7,'30'!E7,'31'!E7) -> 85 | F7: =SUM('01'!F7,'02'!F7,'03'!F7,'04'!F7,'05'!F7,'06'!F7,'07'!F7,'08'!F7,'09'!F7,'10'!F7,'11'!F7,'12'!F7,'13'!F7,'14'!F7,'15'!F7,'16'!F7,'17'!F7,'18'!F7,'19'!F7,'20'!F7,'21'!F7,'22'!F7,'23'!F7,'24'!F7,'25'!F7,'26'!F7,'27'!F7,'28'!F7,'29'!F7,'30'!F7,'31'!F7) -> 94 | G7: =SUM('01'!G7,'02'!G7,'03'!G7,'04'!G7,'05'!G7,'06'!G7,'07'!G7,'08'!G7,'09'!G7,'10'!G7,'11'!G7,'12'!G7,'13'!G7,'14'!G7,'15'!G7,'16'!G7,'17'!G7,'18'!G7,'19'!G7,'20'!G7,'21'!G7,'22'!G7,'23'!G7,'24'!G7,'25'!G7,'26'!G7,'27'!G7,'28'!G7,'29'!G7,'30'!G7,'31'!G7) -> 140 | H7: =SUM('01'!H7,'02'!H7,'03'!H7,'04'!H7,'05'!H7,'06'!H7,'07'!H7,'08'!H7,'09'!H7,'10'!H7,'11'!H7,'12'!H7,'13'!H7,'14'!H7,'15'!H7,'16'!H7,'17'!H7,'18'!H7,'19'!H7,'20'!H7,'21'!H7,'22'!H7,'23'!H7,'24'!H7,'25'!H7,'26'!H7,'27'!H7,'28'!H7,'29'!H7,'30'!H7,'31'!H7) -> 226 | I7: =SUM('01'!I7,'02'!I7,'03'!I7,'04'!I7,'05'!I7,'06'!I7,'07'!I7,'08'!I7,'09'!I7,'10'!I7,'11'!I7,'12'!I7,'13'!I7,'14'!I7,'15'!I7,'16'!I7,'17'!I7,'18'!I7,'19'!I7,'20'!I7,'21'!I7,'22'!I7,'23'!I7,'24'!I7,'25'!I7,'26'!I7,'27'!I7,'28'!I7,'29'!I7,'30'!I7,'31'!I7) -> 114 | J7: =SUM(B7:I7)+SUM(K7) -> 1287 | K7: 43 | L7: =SUM('01'!K7,'02'!K7,'03'!K7,'04'!K7,'05'!K7,'06'!K7,'07'!K7,'08'!K7,'09'!K7,'10'!K7,'11'!K7,'12'!K7,'13'!K7,'14'!K7,'15'!K7,'16'!K7,'17'!K7,'18'!K7,'19'!K7,'20'!K7,'21'!K7,'22'!K7,'23'!K7,'24'!K7,'25'!K7,'26'!K7,'27'!K7,'28'!K7,'29'!K7,'30'!K7,'31'!K7) -> 118 | M7: =IFERROR(J7/L7,"") -> 10.90678
A8: Osoba 7 | B8: =SUM('01'!B8,'02'!B8,'03'!B8,'04'!B8,'05'!B8,'06'!B8,'07'!B8,'08'!B8,'09'!B8,'10'!B8,'11'!B8,'12'!B8,'13'!B8,'14'!B8,'15'!B8,'16'!B8,'17'!B8,'18'!B8,'19'!B8,'20'!B8,'21'!B8,'22'!B8,'23'!B8,'24'!B8,'25'!B8,'26'!B8,'27'!B8,'28'!B8,'29'!B8,'30'!B8,'31'!B8) -> 221 | C8: =SUM('01'!C8,'02'!C8,'03'!C8,'04'!C8,'05'!C8,'06'!C8,'07'!C8,'08'!C8,'09'!C8,'10'!C8,'11'!C8,'12'!C8,'13'!C8,'14'!C8,'15'!C8,'16'!C8,'17'!C8,'18'!C8,'19'!C8,'20'!C8,'21'!C8,'22'!C8,'23'!C8,'24'!C8,'25'!C8,'26'!C8,'27'!C8,'28'!C8,'29'!C8,'30'!C8,'31'!C8) -> 184 | D8: =SUM('01'!D8,'02'!D8,'03'!D8,'04'!D8,'05'!D8,'06'!D8,'07'!D8,'08'!D8,'09'!D8,'10'!D8,'11'!D8,'12'!D8,'13'!D8,'14'!D8,'15'!D8,'16'!D8,'17'!D8,'18'!D8,'19'!D8,'20'!D8,'21'!D8,'22'!D8,'23'!D8,'24'!D8,'25'!D8,'26'!D8,'27'!D8,'28'!D8,'29'!D8,'30'!D8,'31'!D8) -> 97 | E8: =SUM('01'!E8,'02'!E8,'03'!E8,'04'!E8,'05'!E8,'06'!E8,'07'!E8,'08'!E8,'09'!E8,'10'!E8,'11'!E8,'12'!E8,'13'!E8,'14'!E8,'15'!E8,'16'!E8,'17'!E8,'18'!E8,'19'!E8,'20'!E8,'21'!E8,'22'!E8,'23'!E8,'24'!E8,'25'!E8,'26'!E8,'27'!E8,'28'!E8,'29'!E8,'30'!E8,'31'!E8) -> 70 | F8: =SUM('01'!F8,'02'!F8,'03'!F8,'04'!F8,'05'!F8,'06'!F8,'07'!F8,'08'!F8,'09'!F8,'10'!F8,'11'!F8,'12'!F8,'13'!F8,'14'!F8,'15'!F8,'16'!F8,'17'!F8,'18'!F8,'19'!F8,'20'!F8,'21'!F8,'22'!F8,'23'!F8,'24'!F8,'25'!F8,'26'!F8,'27'!F8,'28'!F8,'29'!F8,'30'!F8,'31'!F8) -> 61 | G8: =SUM('01'!G8,'02'!G8,'03'!G8,'04'!G8,'05'!G8,'06'!G8,'07'!G8,'08'!G8,'09'!G8,'10'!G8,'11'!G8,'12'!G8,'13'!G8,'14'!G8,'15'!G8,'16'!G8,'17'!G8,'18'!G8,'19'!G8,'20'!G8,'21'!G8,'22'!G8,'23'!G8,'24'!G8,'25'!G8,'26'!G8,'27'!G8,'28'!G8,'29'!G8,'30'!G8,'31'!G8) -> 122 | H8: =SUM('01'!H8,'02'!H8,'03'!H8,'04'!H8,'05'!H8,'06'!H8,'07'!H8,'08'!H8,'09'!H8,'10'!H8,'11'!H8,'12'!H8,'13'!H8,'14'!H8,'15'!H8,'16'!H8,'17'!H8,'18'!H8,'19'!H8,'20'!H8,'21'!H8,'22'!H8,'23'!H8,'24'!H8,'25'!H8,'26'!H8,'27'!H8,'28'!H8,'29'!H8,'30'!H8,'31'!H8) -> 160 | I8: =SUM('01'!I8,'02'!I8,'03'!I8,'04'!I8,'05'!I8,'06'!I8,'07'!I8,'08'!I8,'09'!I8,'10'!I8,'11'!I8,'12'!I8,'13'!I8,'14'!I8,'15'!I8,'16'!I8,'17'!I8,'18'!I8,'19'!I8,'20'!I8,'21'!I8,'22'!I8,'23'!I8,'24'!I8,'25'!I8,'26'!I8,'27'!I8,'28'!I8,'29'!I8,'30'!I8,'31'!I8) -> 99 | J8: =SUM(B8:I8)+SUM(K8) -> 1099 | K8: 85 | L8: =SUM('01'!K8,'02'!K8,'03'!K8,'04'!K8,'05'!K8,'06'!K8,'07'!K8,'08'!K8,'09'!K8,'10'!K8,'11'!K8,'12'!K8,'13'!K8,'14'!K8,'15'!K8,'16'!K8,'17'!K8,'18'!K8,'19'!K8,'20'!K8,'21'!K8,'22'!K8,'23'!K8,'24'!K8,'25'!K8,'26'!K8,'27'!K8,'28'!K8,'29'!K8,'30'!K8,'31'!K8) -> 126 | M8: =IFERROR(J8/L8,"") -> 8.7222222
A9: Osoba 8 | B9: =SUM('01'!B9,'02'!B9,'03'!B9,'04'!B9,'05'!B9,'06'!B9,'07'!B9,'08'!B9,'09'!B9,'10'!B9,'11'!B9,'12'!B9,'13'!B9,'14'!B9,'15'!B9,'16'!B9,'17'!B9,'18'!B9,'19'!B9,'20'!B9,'21'!B9,'22'!B9,'23'!B9,'24'!B9,'25'!B9,'26'!B9,'27'!B9,'28'!B9,'29'!B9,'30'!B9,'31'!B9) -> 286 | C9: =SUM('01'!C9,'02'!C9,'03'!C9,'04'!C9,'05'!C9,'06'!C9,'07'!C9,'08'!C9,'09'!C9,'10'!C9,'11'!C9,'12'!C9,'13'!C9,'14'!C9,'15'!C9,'16'!C9,'17'!C9,'18'!C9,'19'!C9,'20'!C9,'21'!C9,'22'!C9,'23'!C9,'24'!C9,'25'!C9,'26'!C9,'27'!C9,'28'!C9,'29'!C9,'30'!C9,'31'!C9) -> 154 | D9: =SUM('01'!D9,'02'!D9,'03'!D9,'04'!D9,'05'!D9,'06'!D9,'07'!D9,'08'!D9,'09'!D9,'10'!D9,'11'!D9,'12'!D9,'13'!D9,'14'!D9,'15'!D9,'16'!D9,'17'!D9,'18'!D9,'19'!D9,'20'!D9,'21'!D9,'22'!D9,'23'!D9,'24'!D9,'25'!D9,'26'!D9,'27'!D9,'28'!D9,'29'!D9,'30'!D9,'31'!D9) -> 106 | E9: =SUM('01'!E9,'02'!E9,'03'!E9,'04'!E9,'05'!E9,'06'!E9,'07'!E9,'08'!E9,'09'!E9,'10'!E9,'11'!E9,'12'!E9,'13'!E9,'14'!E9,'15'!E9,'16'!E9,'17'!E9,'18'!E9,'19'!E9,'20'!E9,'21'!E9,'22'!E9,'23'!E9,'24'!E9,'25'!E9,'26'!E9,'27'!E9,'28'!E9,'29'!E9,'30'!E9,'31'!E9) -> 76 | F9: =SUM('01'!F9,'02'!F9,'03'!F9,'04'!F9,'05'!F9,'06'!F9,'07'!F9,'08'!F9,'09'!F9,'10'!F9,'11'!F9,'12'!F9,'13'!F9,'14'!F9,'15'!F9,'16'!F9,'17'!F9,'18'!F9,'19'!F9,'20'!F9,'21'!F9,'22'!F9,'23'!F9,'24'!F9,'25'!F9,'26'!F9,'27'!F9,'28'!F9,'29'!F9,'30'!F9,'31'!F9) -> 79 | G9: =SUM('01'!G9,'02'!G9,'03'!G9,'04'!G9,'05'!G9,'06'!G9,'07'!G9,'08'!G9,'09'!G9,'10'!G9,'11'!G9,'12'!G9,'13'!G9,'14'!G9,'15'!G9,'16'!G9,'17'!G9,'18'!G9,'19'!G9,'20'!G9,'21'!G9,'22'!G9,'23'!G9,'24'!G9,'25'!G9,'26'!G9,'27'!G9,'28'!G9,'29'!G9,'30'!G9,'31'!G9) -> 109 | H9: =SUM('01'!H9,'02'!H9,'03'!H9,'04'!H9,'05'!H9,'06'!H9,'07'!H9,'08'!H9,'09'!H9,'10'!H9,'11'!H9,'12'!H9,'13'!H9,'14'!H9,'15'!H9,'16'!H9,'17'!H9,'18'!H9,'19'!H9,'20'!H9,'21'!H9,'22'!H9,'23'!H9,'24'!H9,'25'!H9,'26'!H9,'27'!H9,'28'!H9,'29'!H9,'30'!H9,'31'!H9) -> 166 | I9: =SUM('01'!I9,'02'!I9,'03'!I9,'04'!I9,'05'!I9,'06'!I9,'07'!I9,'08'!I9,'09'!I9,'10'!I9,'11'!I9,'12'!I9,'13'!I9,'14'!I9,'15'!I9,'16'!I9,'17'!I9,'18'!I9,'19'!I9,'20'!I9,'21'!I9,'22'!I9,'23'!I9,'24'!I9,'25'!I9,'26'!I9,'27'!I9,'28'!I9,'29'!I9,'30'!I9,'31'!I9) -> 85 | J9: =SUM(B9:I9)+SUM(K9) -> 1141 | K9: 80 | L9: =SUM('01'!K9,'02'!K9,'03'!K9,'04'!K9,'05'!K9,'06'!K9,'07'!K9,'08'!K9,'09'!K9,'10'!K9,'11'!K9,'12'!K9,'13'!K9,'14'!K9,'15'!K9,'16'!K9,'17'!K9,'18'!K9,'19'!K9,'20'!K9,'21'!K9,'22'!K9,'23'!K9,'24'!K9,'25'!K9,'26'!K9,'27'!K9,'28'!K9,'29'!K9,'30'!K9,'31'!K9) -> 116 | M9: =IFERROR(J9/L9,"") -> 9.8362069
A10: Osoba 9 | B10: =SUM('01'!B10,'02'!B10,'03'!B10,'04'!B10,'05'!B10,'06'!B10,'07'!B10,'08'!B10,'09'!B10,'10'!B10,'11'!B10,'12'!B10,'13'!B10,'14'!B10,'15'!B10,'16'!B10,'17'!B10,'18'!B10,'19'!B10,'20'!B10,'21'!B10,'22'!B10,'23'!B10,'24'!B10,'25'!B10,'26'!B10,'27'!B10,'28'!B10,'29'!B10,'30'!B10,'31'!B10) -> 269 | C10: =SUM('01'!C10,'02'!C10,'03'!C10,'04'!C10,'05'!C10,'06'!C10,'07'!C10,'08'!C10,'09'!C10,'10'!C10,'11'!C10,'12'!C10,'13'!C10,'14'!C10,'15'!C10,'16'!C10,'17'!C10,'18'!C10,'19'!C10,'20'!C10,'21'!C10,'22'!C10,'23'!C10,'24'!C10,'25'!C10,'26'!C10,'27'!C10,'28'!C10,'29'!C10,'30'!C10,'31'!C10) -> 165 | D10: =SUM('01'!D10,'02'!D10,'03'!D10,'04'!D10,'05'!D10,'06'!D10,'07'!D10,'08'!D10,'09'!D10,'10'!D10,'11'!D10,'12'!D10,'13'!D10,'14'!D10,'15'!D10,'16'!D10,'17'!D10,'18'!D10,'19'!D10,'20'!D10,'21'!D10,'22'!D10,'23'!D10,'24'!D10,'25'!D10,'26'!D10,'27'!D10,'28'!D10,'29'!D10,'30'!D10,'31'!D10) -> 111 | E10: =SUM('01'!E10,'02'!E10,'03'!E10,'04'!E10,'05'!E10,'06'!E10,'07'!E10,'08'!E10,'09'!E10,'10'!E10,'11'!E10,'12'!E10,'13'!E10,'14'!E10,'15'!E10,'16'!E10,'17'!E10,'18'!E10,'19'!E10,'20'!E10,'21'!E10,'22'!E10,'23'!E10,'24'!E10,'25'!E10,'26'!E10,'27'!E10,'28'!E10,'29'!E10,'30'!E10,'31'!E10) -> 78 | F10: =SUM('01'!F10,'02'!F10,'03'!F10,'04'!F10,'05'!F10,'06'!F10,'07'!F10,'08'!F10,'09'!F10,'10'!F10,'11'!F10,'12'!F10,'13'!F10,'14'!F10,'15'!F10,'16'!F10,'17'!F10,'18'!F10,'19'!F10,'20'!F10,'21'!F10,'22'!F10,'23'!F10,'24'!F10,'25'!F10,'26'!F10,'27'!F10,'28'!F10,'29'!F10,'30'!F10,'31'!F10) -> 82 | G10: =SUM('01'!G10,'02'!G10,'03'!G10,'04'!G10,'05'!G10,'06'!G10,'07'!G10,'08'!G10,'09'!G10,'10'!G10,'11'!G10,'12'!G10,'13'!G10,'14'!G10,'15'!G10,'16'!G10,'17'!G10,'18'!G10,'19'!G10,'20'!G10,'21'!G10,'22'!G10,'23'!G10,'24'!G10,'25'!G10,'26'!G10,'27'!G10,'28'!G10,'29'!G10,'30'!G10,'31'!G10) -> 128 | H10: =SUM('01'!H10,'02'!H10,'03'!H10,'04'!H10,'05'!H10,'06'!H10,'07'!H10,'08'!H10,'09'!H10,'10'!H10,'11'!H10,'12'!H10,'13'!H10,'14'!H10,'15'!H10,'16'!H10,'17'!H10,'18'!H10,'19'!H10,'20'!H10,'21'!H10,'22'!H10,'23'!H10,'24'!H10,'25'!H10,'26'!H10,'27'!H10,'28'!H10,'29'!H10,'30'!H10,'31'!H10) -> 236 | I10: =SUM('01'!I10,'02'!I10,'03'!I10,'04'!I10,'05'!I10,'06'!I10,'07'!I10,'08'!I10,'09'!I10,'10'!I10,'11'!I10,'12'!I10,'13'!I10,'14'!I10,'15'!I10,'16'!I10,'17'!I10,'18'!I10,'19'!I10,'20'!I10,'21'!I10,'22'!I10,'23'!I10,'24'!I10,'25'!I10,'26'!I10,'27'!I10,'28'!I10,'29'!I10,'30'!I10,'31'!I10) -> 122 | J10: =SUM(B10:I10)+SUM(K10) -> 1234 | K10: 43 | L10: =SUM('01'!K10,'02'!K10,'03'!K10,'04'!K10,'05'!K10,'06'!K10,'07'!K10,'08'!K10,'09'!K10,'10'!K10,'11'!K10,'12'!K10,'13'!K10,'14'!K10,'15'!K10,'16'!K10,'17'!K10,'18'!K10,'19'!K10,'20'!K10,'21'!K10,'22'!K10,'23'!K10,'24'!K10,'25'!K10,'26'!K10,'27'!K10,'28'!K10,'29'!K10,'30'!K10,'31'!K10) -> 148 | M10: =IFERROR(J10/L10,"") -> 8.3378378
A11: Osoba 10 | B11: =SUM('01'!B11,'02'!B11,'03'!B11,'04'!B11,'05'!B11,'06'!B11,'07'!B11,'08'!B11,'09'!B11,'10'!B11,'11'!B11,'12'!B11,'13'!B11,'14'!B11,'15'!B11,'16'!B11,'17'!B11,'18'!B11,'19'!B11,'20'!B11,'21'!B11,'22'!B11,'23'!B11,'24'!B11,'25'!B11,'26'!B11,'27'!B11,'28'!B11,'29'!B11,'30'!B11,'31'!B11) -> 253 | C11: =SUM('01'!C11,'02'!C11,'03'!C11,'04'!C11,'05'!C11,'06'!C11,'07'!C11,'08'!C11,'09'!C11,'10'!C11,'11'!C11,'12'!C11,'13'!C11,'14'!C11,'15'!C11,'16'!C11,'17'!C11,'18'!C11,'19'!C11,'20'!C11,'21'!C11,'22'!C11,'23'!C11,'24'!C11,'25'!C11,'26'!C11,'27'!C11,'28'!C11,'29'!C11,'30'!C11,'31'!C11) -> 148 | D11: =SUM('01'!D11,'02'!D11,'03'!D11,'04'!D11,'05'!D11,'06'!D11,'07'!D11,'08'!D11,'09'!D11,'10'!D11,'11'!D11,'12'!D11,'13'!D11,'14'!D11,'15'!D11,'16'!D11,'17'!D11,'18'!D11,'19'!D11,'20'!D11,'21'!D11,'22'!D11,'23'!D11,'24'!D11,'25'!D11,'26'!D11,'27'!D11,'28'!D11,'29'!D11,'30'!D11,'31'!D11) -> 114 | E11: =SUM('01'!E11,'02'!E11,'03'!E11,'04'!E11,'05'!E11,'06'!E11,'07'!E11,'08'!E11,'09'!E11,'10'!E11,'11'!E11,'12'!E11,'13'!E11,'14'!E11,'15'!E11,'16'!E11,'17'!E11,'18'!E11,'19'!E11,'20'!E11,'21'!E11,'22'!E11,'23'!E11,'24'!E11,'25'!E11,'26'!E11,'27'!E11,'28'!E11,'29'!E11,'30'!E11,'31'!E11) -> 73 | F11: =SUM('01'!F11,'02'!F11,'03'!F11,'04'!F11,'05'!F11,'06'!F11,'07'!F11,'08'!F11,'09'!F11,'10'!F11,'11'!F11,'12'!F11,'13'!F11,'14'!F11,'15'!F11,'16'!F11,'17'!F11,'18'!F11,'19'!F11,'20'!F11,'21'!F11,'22'!F11,'23'!F11,'24'!F11,'25'!F11,'26'!F11,'27'!F11,'28'!F11,'29'!F11,'30'!F11,'31'!F11) -> 75 | G11: =SUM('01'!G11,'02'!G11,'03'!G11,'04'!G11,'05'!G11,'06'!G11,'07'!G11,'08'!G11,'09'!G11,'10'!G11,'11'!G11,'12'!G11,'13'!G11,'14'!G11,'15'!G11,'16'!G11,'17'!G11,'18'!G11,'19'!G11,'20'!G11,'21'!G11,'22'!G11,'23'!G11,'24'!G11,'25'!G11,'26'!G11,'27'!G11,'28'!G11,'29'!G11,'30'!G11,'31'!G11) -> 115 | H11: =SUM('01'!H11,'02'!H11,'03'!H11,'04'!H11,'05'!H11,'06'!H11,'07'!H11,'08'!H11,'09'!H11,'10'!H11,'11'!H11,'12'!H11,'13'!H11,'14'!H11,'15'!H11,'16'!H11,'17'!H11,'18'!H11,'19'!H11,'20'!H11,'21'!H11,'22'!H11,'23'!H11,'24'!H11,'25'!H11,'26'!H11,'27'!H11,'28'!H11,'29'!H11,'30'!H11,'31'!H11) -> 200 | I11: =SUM('01'!I11,'02'!I11,'03'!I11,'04'!I11,'05'!I11,'06'!I11,'07'!I11,'08'!I11,'09'!I11,'10'!I11,'11'!I11,'12'!I11,'13'!I11,'14'!I11,'15'!I11,'16'!I11,'17'!I11,'18'!I11,'19'!I11,'20'!I11,'21'!I11,'22'!I11,'23'!I11,'24'!I11,'25'!I11,'26'!I11,'27'!I11,'28'!I11,'29'!I11,'30'!I11,'31'!I11) -> 88 | J11: =SUM(B11:I11)+SUM(K11) -> 1098 | K11: 32 | L11: =SUM('01'!K11,'02'!K11,'03'!K11,'04'!K11,'05'!K11,'06'!K11,'07'!K11,'08'!K11,'09'!K11,'10'!K11,'11'!K11,'12'!K11,'13'!K11,'14'!K11,'15'!K11,'16'!K11,'17'!K11,'18'!K11,'19'!K11,'20'!K11,'21'!K11,'22'!K11,'23'!K11,'24'!K11,'25'!K11,'26'!K11,'27'!K11,'28'!K11,'29'!K11,'30'!K11,'31'!K11) -> 118 | M11: =IFERROR(J11/L11,"") -> 9.3050847
A12: Osoba 11 | B12: =SUM('01'!B12,'02'!B12,'03'!B12,'04'!B12,'05'!B12,'06'!B12,'07'!B12,'08'!B12,'09'!B12,'10'!B12,'11'!B12,'12'!B12,'13'!B12,'14'!B12,'15'!B12,'16'!B12,'17'!B12,'18'!B12,'19'!B12,'20'!B12,'21'!B12,'22'!B12,'23'!B12,'24'!B12,'25'!B12,'26'!B12,'27'!B12,'28'!B12,'29'!B12,'30'!B12,'31'!B12) -> 263 | C12: =SUM('01'!C12,'02'!C12,'03'!C12,'04'!C12,'05'!C12,'06'!C12,'07'!C12,'08'!C12,'09'!C12,'10'!C12,'11'!C12,'12'!C12,'13'!C12,'14'!C12,'15'!C12,'16'!C12,'17'!C12,'18'!C12,'19'!C12,'20'!C12,'21'!C12,'22'!C12,'23'!C12,'24'!C12,'25'!C12,'26'!C12,'27'!C12,'28'!C12,'29'!C12,'30'!C12,'31'!C12) -> 155 | D12: =SUM('01'!D12,'02'!D12,'03'!D12,'04'!D12,'05'!D12,'06'!D12,'07'!D12,'08'!D12,'09'!D12,'10'!D12,'11'!D12,'12'!D12,'13'!D12,'14'!D12,'15'!D12,'16'!D12,'17'!D12,'18'!D12,'19'!D12,'20'!D12,'21'!D12,'22'!D12,'23'!D12,'24'!D12,'25'!D12,'26'!D12,'27'!D12,'28'!D12,'29'!D12,'30'!D12,'31'!D12) -> 109 | E12: =SUM('01'!E12,'02'!E12,'03'!E12,'04'!E12,'05'!E12,'06'!E12,'07'!E12,'08'!E12,'09'!E12,'10'!E12,'11'!E12,'12'!E12,'13'!E12,'14'!E12,'15'!E12,'16'!E12,'17'!E12,'18'!E12,'19'!E12,'20'!E12,'21'!E12,'22'!E12,'23'!E12,'24'!E12,'25'!E12,'26'!E12,'27'!E12,'28'!E12,'29'!E12,'30'!E12,'31'!E12) -> 69 | F12: =SUM('01'!F12,'02'!F12,'03'!F12,'04'!F12,'05'!F12,'06'!F12,'07'!F12,'08'!F12,'09'!F12,'10'!F12,'11'!F12,'12'!F12,'13'!F12,'14'!F12,'15'!F12,'16'!F12,'17'!F12,'18'!F12,'19'!F12,'20'!F12,'21'!F12,'22'!F12,'23'!F12,'24'!F12,'25'!F12,'26'!F12,'27'!F12,'28'!F12,'29'!F12,'30'!F12,'31'!F12) -> 70 | G12: =SUM('01'!G12,'02'!G12,'03'!G12,'04'!G12,'05'!G12,'06'!G12,'07'!G12,'08'!G12,'09'!G12,'10'!G12,'11'!G12,'12'!G12,'13'!G12,'14'!G12,'15'!G12,'16'!G12,'17'!G12,'18'!G12,'19'!G12,'20'!G12,'21'!G12,'22'!G12,'23'!G12,'24'!G12,'25'!G12,'26'!G12,'27'!G12,'28'!G12,'29'!G12,'30'!G12,'31'!G12) -> 115 | H12: =SUM('01'!H12,'02'!H12,'03'!H12,'04'!H12,'05'!H12,'06'!H12,'07'!H12,'08'!H12,'09'!H12,'10'!H12,'11'!H12,'12'!H12,'13'!H12,'14'!H12,'15'!H12,'16'!H12,'17'!H12,'18'!H12,'19'!H12,'20'!H12,'21'!H12,'22'!H12,'23'!H12,'24'!H12,'25'!H12,'26'!H12,'27'!H12,'28'!H12,'29'!H12,'30'!H12,'31'!H12) -> 224 | I12: =SUM('01'!I12,'02'!I12,'03'!I12,'04'!I12,'05'!I12,'06'!I12,'07'!I12,'08'!I12,'09'!I12,'10'!I12,'11'!I12,'12'!I12,'13'!I12,'14'!I12,'15'!I12,'16'!I12,'17'!I12,'18'!I12,'19'!I12,'20'!I12,'21'!I12,'22'!I12,'23'!I12,'24'!I12,'25'!I12,'26'!I12,'27'!I12,'28'!I12,'29'!I12,'30'!I12,'31'!I12) -> 110 | J12: =SUM(B12:I12)+SUM(K12) -> 1192 | K12: 77 | L12: =SUM('01'!K12,'02'!K12,'03'!K12,'04'!K12,'05'!K12,'06'!K12,'07'!K12,'08'!K12,'09'!K12,'10'!K12,'11'!K12,'12'!K12,'13'!K12,'14'!K12,'15'!K12,'16'!K12,'17'!K12,'18'!K12,'19'!K12,'20'!K12,'21'!K12,'22'!K12,'23'!K12,'24'!K12,'25'!K12,'26'!K12,'27'!K12,'28'!K12,'29'!K12,'30'!K12,'31'!K12) -> 132 | M12: =IFERROR(J12/L12,"") -> 9.030303
A13: Osoba 12 | B13: =SUM('01'!B13,'02'!B13,'03'!B13,'04'!B13,'05'!B13,'06'!B13,'07'!B13,'08'!B13,'09'!B13,'10'!B13,'11'!B13,'12'!B13,'13'!B13,'14'!B13,'15'!B13,'16'!B13,'17'!B13,'18'!B13,'19'!B13,'20'!B13,'21'!B13,'22'!B13,'23'!B13,'24'!B13,'25'!B13,'26'!B13,'27'!B13,'28'!B13,'29'!B13,'30'!B13,'31'!B13) -> 270 | C13: =SUM('01'!C13,'02'!C13,'03'!C13,'04'!C13,'05'!C13,'06'!C13,'07'!C13,'08'!C13,'09'!C13,'10'!C13,'11'!C13,'12'!C13,'13'!C13,'14'!C13,'15'!C13,'16'!C13,'17'!C13,'18'!C13,'19'!C13,'20'!C13,'21'!C13,'22'!C13,'23'!C13,'24'!C13,'25'!C13,'26'!C13,'27'!C13,'28'!C13,'29'!C13,'30'!C13,'31'!C13) -> 140 | D13: =SUM('01'!D13,'02'!D13,'03'!D13,'04'!D13,'05'!D13,'06'!D13,'07'!D13,'08'!D13,'09'!D13,'10'!D13,'11'!D13,'12'!D13,'13'!D13,'14'!D13,'15'!D13,'16'!D13,'17'!D13,'18'!D13,'19'!D13,'20'!D13,'21'!D13,'22'!D13,'23'!D13,'24'!D13,'25'!D13,'26'!D13,'27'!D13,'28'!D13,'29'!D13,'30'!D13,'31'!D13) -> 130 | E13: =SUM('01'!E13,'02'!E13,'03'!E13,'04'!E13,'05'!E13,'06'!E13,'07'!E13,'08'!E13,'09'!E13,'10'!E13,'11'!E13,'12'!E13,'13'!E13,'14'!E13,'15'!E13,'16'!E13,'17'!E13,'18'!E13,'19'!E13,'20'!E13,'21'!E13,'22'!E13,'23'!E13,'24'!E13,'25'!E13,'26'!E13,'27'!E13,'28'!E13,'29'!E13,'30'!E13,'31'!E13) -> 88 | F13: =SUM('01'!F13,'02'!F13,'03'!F13,'04'!F13,'05'!F13,'06'!F13,'07'!F13,'08'!F13,'09'!F13,'10'!F13,'11'!F13,'12'!F13,'13'!F13,'14'!F13,'15'!F13,'16'!F13,'17'!F13,'18'!F13,'19'!F13,'20'!F13,'21'!F13,'22'!F13,'23'!F13,'24'!F13,'25'!F13,'26'!F13,'27'!F13,'28'!F13,'29'!F13,'30'!F13,'31'!F13) -> 67 | G13: =SUM('01'!G13,'02'!G13,'03'!G13,'04'!G13,'05'!G13,'06'!G13,'07'!G13,'08'!G13,'09'!G13,'10'!G13,'11'!G13,'12'!G13,'13'!G13,'14'!G13,'15'!G13,'16'!G13,'17'!G13,'18'!G13,'19'!G13,'20'!G13,'21'!G13,'22'!G13,'23'!G13,'24'!G13,'25'!G13,'26'!G13,'27'!G13,'28'!G13,'29'!G13,'30'!G13,'31'!G13) -> 138 | H13: =SUM('01'!H13,'02'!H13,'03'!H13,'04'!H13,'05'!H13,'06'!H13,'07'!H13,'08'!H13,'09'!H13,'10'!H13,'11'!H13,'12'!H13,'13'!H13,'14'!H13,'15'!H13,'16'!H13,'17'!H13,'18'!H13,'19'!H13,'20'!H13,'21'!H13,'22'!H13,'23'!H13,'24'!H13,'25'!H13,'26'!H13,'27'!H13,'28'!H13,'29'!H13,'30'!H13,'31'!H13) -> 197 | I13: =SUM('01'!I13,'02'!I13,'03'!I13,'04'!I13,'05'!I13,'06'!I13,'07'!I13,'08'!I13,'09'!I13,'10'!I13,'11'!I13,'12'!I13,'13'!I13,'14'!I13,'15'!I13,'16'!I13,'17'!I13,'18'!I13,'19'!I13,'20'!I13,'21'!I13,'22'!I13,'23'!I13,'24'!I13,'25'!I13,'26'!I13,'27'!I13,'28'!I13,'29'!I13,'30'!I13,'31'!I13) -> 80 | J13: =SUM(B13:I13)+SUM(K13) -> 1168 | K13: 58 | L13: =SUM('01'!K13,'02'!K13,'03'!K13,'04'!K13,'05'!K13,'06'!K13,'07'!K13,'08'!K13,'09'!K13,'10'!K13,'11'!K13,'12'!K13,'13'!K13,'14'!K13,'15'!K13,'16'!K13,'17'!K13,'18'!K13,'19'!K13,'20'!K13,'21'!K13,'22'!K13,'23'!K13,'24'!K13,'25'!K13,'26'!K13,'27'!K13,'28'!K13,'29'!K13,'30'!K13,'31'!K13) -> 132 | M13: =IFERROR(J13/L13,"") -> 8.8484848
... A22: Osoba 21 | B22: =SUM('01'!B22,'02'!B22,'03'!B22,'04'!B22,'05'!B22,'06'!B22,'07'!B22,'08'!B22,'09'!B22,'10'!B22,'11'!B22,'12'!B22,'13'!B22,'14'!B22,'15'!B22,'16'!B22,'17'!B22,'18'!B22,'19'!B22,'20'!B22,'21'!B22,'22'!B22,'23'!B22,'24'!B22,'25'!B22,'26'!B22,'27'!B22,'28'!B22,'29'!B22,'30'!B22,'31'!B22) -> 232 | C22: =SUM('01'!C22,'02'!C22,'03'!C22,'04'!C22,'05'!C22,'06'!C22,'07'!C22,'08'!C22,'09'!C22,'10'!C22,'11'!C22,'12'!C22,'13'!C22,'14'!C22,'15'!C22,'16'!C22,'17'!C22,'18'!C22,'19'!C22,'20'!C22,'21'!C22,'22'!C22,'23'!C22,'24'!C22,'25'!C22,'26'!C22,'27'!C22,'28'!C22,'29'!C22,'30'!C22,'31'!C22) -> 156 | D22: =SUM('01'!D22,'02'!D22,'03'!D22,'04'!D22,'05'!D22,'06'!D22,'07'!D22,'08'!D22,'09'!D22,'10'!D22,'11'!D22,'12'!D22,'13'!D22,'14'!D22,'15'!D22,'16'!D22,'17'!D22,'18'!D22,'19'!D22,'20'!D22,'21'!D22,'22'!D22,'23'!D22,'24'!D22,'25'!D22,'26'!D22,'27'!D22,'28'!D22,'29'!D22,'30'!D22,'31'!D22) -> 95 | E22: =SUM('01'!E22,'02'!E22,'03'!E22,'04'!E22,'05'!E22,'06'!E22,'07'!E22,'08'!E22,'09'!E22,'10'!E22,'11'!E22,'12'!E22,'13'!E22,'14'!E22,'15'!E22,'16'!E22,'17'!E22,'18'!E22,'19'!E22,'20'!E22,'21'!E22,'22'!E22,'23'!E22,'24'!E22,'25'!E22,'26'!E22,'27'!E22,'28'!E22,'29'!E22,'30'!E22,'31'!E22) -> 96 | F22: =SUM('01'!F22,'02'!F22,'03'!F22,'04'!F22,'05'!F22,'06'!F22,'07'!F22,'08'!F22,'09'!F22,'10'!F22,'11'!F22,'12'!F22,'13'!F22,'14'!F22,'15'!F22,'16'!F22,'17'!F22,'18'!F22,'19'!F22,'20'!F22,'21'!F22,'22'!F22,'23'!F22,'24'!F22,'25'!F22,'26'!F22,'27'!F22,'28'!F22,'29'!F22,'30'!F22,'31'!F22) -> 97 | G22: =SUM('01'!G22,'02'!G22,'03'!G22,'04'!G22,'05'!G22,'06'!G22,'07'!G22,'08'!G22,'09'!G22,'10'!G22,'11'!G22,'12'!G22,'13'!G22,'14'!G22,'15'!G22,'16'!G22,'17'!G22,'18'!G22,'19'!G22,'20'!G22,'21'!G22,'22'!G22,'23'!G22,'24'!G22,'25'!G22,'26'!G22,'27'!G22,'28'!G22,'29'!G22,'30'!G22,'31'!G22) -> 130 | H22: =SUM('01'!H22,'02'!H22,'03'!H22,'04'!H22,'05'!H22,'06'!H22,'07'!H22,'08'!H22,'09'!H22,'10'!H22,'11'!H22,'12'!H22,'13'!H22,'14'!H22,'15'!H22,'16'!H22,'17'!H22,'18'!H22,'19'!H22,'20'!H22,'21'!H22,'22'!H22,'23'!H22,'24'!H22,'25'!H22,'26'!H22,'27'!H22,'28'!H22,'29'!H22,'30'!H22,'31'!H22) -> 213 | I22: =SUM('01'!I22,'02'!I22,'03'!I22,'04'!I22,'05'!I22,'06'!I22,'07'!I22,'08'!I22,'09'!I22,'10'!I22,'11'!I22,'12'!I22,'13'!I22,'14'!I22,'15'!I22,'16'!I22,'17'!I22,'18'!I22,'19'!I22,'20'!I22,'21'!I22,'22'!I22,'23'!I22,'24'!I22,'25'!I22,'26'!I22,'27'!I22,'28'!I22,'29'!I22,'30'!I22,'31'!I22) -> 119 | J22: =SUM(B22:I22)+SUM(K22) -> 1225 | K22: 87 | L22: =SUM('01'!K22,'02'!K22,'03'!K22,'04'!K22,'05'!K22,'06'!K22,'07'!K22,'08'!K22,'09'!K22,'10'!K22,'11'!K22,'12'!K22,'13'!K22,'14'!K22,'15'!K22,'16'!K22,'17'!K22,'18'!K22,'19'!K22,'20'!K22,'21'!K22,'22'!K22,'23'!K22,'24'!K22,'25'!K22,'26'!K22,'27'!K22,'28'!K22,'29'!K22,'30'!K22,'31'!K22) -> 134 | M22: =IFERROR(J22/L22,"") -> 9.141791

Sheet 01
A1: Osoba | B1: L.Telefonow | C1: L. maili DWS | D1: L.Maili NTO | E1: L.Maili Vouchery | F1: L.Maili MDA | G1: L.TODO | H1: L.Chat | I1: Liczba NTO | J1: suma | K1: rbh | L1: srednia zadan/godz
A2: Osoba 1 | J2: =SUM(B2:I2) -> 0 | L2: =IFERROR(J2/K2,"")
A3: Osoba 2 | J3: =SUM(B3:I3) -> 0 | L3: =IFERROR(J3/K3,"")
A4: Osoba 3 | J4: =SUM(B4:I4) -> 0 | L4: =IFERROR(J4/K4,"")
A5: Osoba 4 | J5: =SUM(B5:I5) -> 0 | L5: =IFERROR(J5/K5,"")
A6: Osoba 5 | J6: =SUM(B6:I6) -> 0 | L6: =IFERROR(J6/K6,"")
A7: Osoba 6 | J7: =SUM(B7:I7) -> 0 | L7: =IFERROR(J7/K7,"")
A8: Osoba 7 | J8: =SUM(B8:I8) -> 0 | L8: =IFERROR(J8/K8,"")
A9: Osoba 8 | J9: =SUM(B9:I9) -> 0 | L9: =IFERROR(J9/K9,"")
A10: Osoba 9 | J10: =SUM(B10:I10) -> 0 | L10: =IFERROR(J10/K10,"")
A11: Osoba 10 | J11: =SUM(B11:I11) -> 0 | L11: =IFERROR(J11/K11,"")
A12: Osoba 11 | J12: =SUM(B12:I12) -> 0 | L12: =IFERROR(J12/K12,"")
A13: Osoba 12 | J13: =SUM(B13:I13) -> 0 | L13: =IFERROR(J13/K13,"")
... A22: Osoba 21 | J22: =SUM(B22:I22) -> 0 | L22: =IFERROR(J22/K22,"")

Sheet 02
A1: Osoba | B1: L.Telefonow | C1: L. maili DWS | D1: L.Maili NTO | E1: L.Maili Vouchery | F1: L.Maili MDA | G1: L.TODO | H1: L.Chat | I1: Liczba NTO | J1: suma | K1: rbh | L1: srednia zadan/godz
A2: Osoba 1 | J2: =SUM(B2:I2) -> 0 | L2: =IFERROR(J2/K2,"")
A3: Osoba 2 | J3: =SUM(B3:I3) -> 0 | L3: =IFERROR(J3/K3,"")
A4: Osoba 3 | J4: =SUM(B4:I4) -> 0 | L4: =IFERROR(J4/K4,"")
A5: Osoba 4 | J5: =SUM(B5:I5) -> 0 | L5: =IFERROR(J5/K5,"")
A6: Osoba 5 | J6: =SUM(B6:I6) -> 0 | L6: =IFERROR(J6/K6,"")
A7: Osoba 6 | J7: =SUM(B7:I7) -> 0 | L7: =IFERROR(J7/K7,"")
A8: Osoba 7 | J8: =SUM(B8:I8) -> 0 | L8: =IFERROR(J8/K8,"")
A9: Osoba 8 | J9: =SUM(B9:I9) -> 0 | L9: =IFERROR(J9/K9,"")
A10: Osoba 9 | J10: =SUM(B10:I10) -> 0 | L10: =IFERROR(J10/K10,"")
A11: Osoba 10 | J11: =SUM(B11:I11) -> 0 | L11: =IFERROR(J11/K11,"")
A12: Osoba 11 | J12: =SUM(B12:I12) -> 0 | L12: =IFERROR(J12/K12,"")
A13: Osoba 12 | J13: =SUM(B13:I13) -> 0 | L13: =IFERROR(J13/K13,"")
... A22: Osoba 21 | J22: =SUM(B22:I22) -> 0 | L22: =IFERROR(J22/K22,"")

Sheet 03
A1: Osoba | B1: L.Telefonow | C1: L. maili DWS | D1: L.Maili NTO | E1: L.Maili Vouchery | F1: L.Maili MDA | G1: L.TODO | H1: L.Chat | I1: Liczba NTO | J1: suma | K1: rbh | L1: srednia zadan/godz
A2: Osoba 1 | J2: =SUM(B2:I2) -> 0 | L2: =IFERROR(J2/K2,"")
A3: Osoba 2 | J3: =SUM(B3:I3) -> 0 | L3: =IFERROR(J3/K3,"")
A4: Osoba 3 | J4: =SUM(B4:I4) -> 0 | L4: =IFERROR(J4/K4,"")
A5: Osoba 4 | J5: =SUM(B5:I5) -> 0 | L5: =IFERROR(J5/K5,"")
A6: Osoba 5 | J6: =SUM(B6:I6) -> 0 | L6: =IFERROR(J6/K6,"")
A7: Osoba 6 | J7: =SUM(B7:I7) -> 0 | L7: =IFERROR(J7/K7,"")
A8: Osoba 7 | J8: =SUM(B8:I8) -> 0 | L8: =IFERROR(J8/K8,"")
A9: Osoba 8 | J9: =SUM(B9:I9) -> 0 | L9: =IFERROR(J9/K9,"")
A10: Osoba 9 | J10: =SUM(B10:I10) -> 0 | L10: =IFERROR(J10/K10,"")
A11: Osoba 10 | J11: =SUM(B11:I11) -> 0 | L11: =IFERROR(J11/K11,"")
A12: Osoba 11 | J12: =SUM(B12:I12) -> 0 | L12: =IFERROR(J12/K12,"")
A13: Osoba 12 | J13: =SUM(B13:I13) -> 0 | L13: =IFERROR(J13/K13,"")
... A22: Osoba 21 | J22: =SUM(B22:I22) -> 0 | L22: =IFERROR(J22/K22,"")

Sheet 04
A1: Osoba | B1: L.Telefonow | C1: L. maili DWS | D1: L.Maili NTO | E1: L.Maili Vouchery | F1: L.Maili MDA | G1: L.TODO | H1: L.Chat | I1: Liczba NTO | J1: suma | K1: rbh | L1: srednia zadan/godz
A2: Osoba 1 | J2: =SUM(B2:I2) -> 0 | L2: =IFERROR(J2/K2,"")
A3: Osoba 2 | J3: =SUM(B3:I3) -> 0 | L3: =IFERROR(J3/K3,"")
A4: Osoba 3 | B4: 24 | C4: 3 | D4: 9 | E4: 6 | F4: 8 | G4: 11 | H4: 9 | I4: 9 | J4: =SUM(B4:I4) -> 79 | K4: 8 | L4: =IFERROR(J4/K4,"") -> 9.875
A5: Osoba 4 | B5: 20 | C5: 3 | D5: 3 | E5: 8 | F5: 5 | G5: 8 | H5: 20 | I5: 2 | J5: =SUM(B5:I5) -> 69 | K5: 8 | L5: =IFERROR(J5/K5,"") -> 8.625
A6: Osoba 5 | B6: 12 | C6: 11 | D6: 6 | E6: 1 | F6: 2 | G6: 11 | H6: 6 | I6: 7 | J6: =SUM(B6:I6) -> 56 | K6: 8 | L6: =IFERROR(J6/K6,"") -> 7
A7: Osoba 6 | B7: 17 | C7: 4 | D7: 2 | E7: 1 | F7: 4 | G7: 5 | H7: 4 | I7: 8 | J7: =SUM(B7:I7) -> 45 | K7: 6 | L7: =IFERROR(J7/K7,"") -> 7.5
A8: Osoba 7 | B8: 17 | C8: 9 | D8: 3 | E8: 4 | F8: 5 | G8: 7 | H8: 5 | I8: 5 | J8: =SUM(B8:I8) -> 55 | K8: 8 | L8: =IFERROR(J8/K8,"") -> 6.875
A9: Osoba 8 | J9: =SUM(B9:I9) -> 0 | L9: =IFERROR(J9/K9,"")
A10: Osoba 9 | B10: 8 | C10: 5 | D10: 5 | E10: 2 | F10: 1 | G10: 2 | H10: 17 | I10: 8 | J10: =SUM(B10:I10) -> 48 | K10: 8 | L10: =IFERROR(J10/K10,"") -> 6
A11: Osoba 10 | B11: 11 | C11: 10 | D11: 10 | E11: 4 | F11: 3 | G11: 8 | H11: 15 | I11: 2 | J11: =SUM(B11:I11) -> 63 | K11: 6 | L11: =IFERROR(J11/K11,"") -> 10.5
A12: Osoba 11 | B12: 11 | C12: 3 | D12: 6 | E12: 5 | F12: 1 | G12: 5 | H12: 8 | I12: 7 | J12: =SUM(B12:I12) -> 46 | K12: 8 | L12: =IFERROR(J12/K12,"") -> 5.75
A13: Osoba 12 | J13: =SUM(B13:I13) -> 0 | L13: =IFERROR(J13/K13,"")
A14: Osoba 13 | B14: 19 | C14: 7 | D14: 2 | E14: 6 | F14: 5 | G14: 8 | H14: 5 | I14: 2 | J14: =SUM(B14:I14) -> 54 | K14: 8 | L14: =IFERROR(J14/K14,"") -> 6.75
A15: Osoba 14 | B15: 25 | C15: 6 | D15: 2 | E15: 6 | F15: 6 | G15: 11 | H15: 17 | I15: 3 | J15: =SUM(B15:I15) -> 76 | K15: 4 | L15: =IFERROR(J15/K15,"") -> 19
A16: Osoba 15 | B16: 9 | C16: 9 | D16: 4 | E16: 3 | F16: 5 | G16: 5 | H16: 10 | I16: 4 | J16: =SUM(B16:I16) -> 49 | K16: 8 | L16: =IFERROR(J16/K16,"") -> 6.125
A17: Osoba 16 | B17: 22 | C17: 6 | D17: 8 | E17: 8 | F17: 2 | G17: 8 | H17: 4 | I17: 2 | J17: =SUM(B17:I17) -> 60 | K17: 8 | L17: =IFERROR(J17/K17,"") -> 7.5
A18: Osoba 17 | J18: =SUM(B18:I18) -> 0 | L18: =IFERROR(J18/K18,"")
A19: Osoba 18 | B19: 12 | C19: 14 | D19: 8 | E19: 5 | F19: 7 | G19: 11 | H19: 18 | I19: 5 | J19: =SUM(B19:I19) -> 80 | K19: 8 | L19: =IFERROR(J19/K19,"") -> 10
A20: Osoba 19 | B20: 7 | C20: 5 | D20: 5 | E20: 8 | F20: 2 | G20: 6 | H20: 9 | I20: 4 | J20: =SUM(B20:I20) -> 46 | K20: 8 | L20: =IFERROR(J20/K20,"") -> 5.75
A21: Osoba 20 | J21: =SUM(B21:I21) -> 0 | L21: =IFERROR(J21/K21,"")
A22: Osoba 21 | B22: 12 | C22: 3 | D22: 2 | E22: 3 | F22: 5 | G22: 7 | H22: 19 | I22: 10 | J22: =SUM(B22:I22) -> 61 | K22: 8 | L22: =IFERROR(J22/K22,"") -> 7.625

Sheet 05
A1: Osoba | B1: L.Telefonow | C1: L. maili DWS | D1: L.Maili NTO | E1: L.Maili Vouchery | F1: L.Maili MDA | G1: L.TODO | H1: L.Chat | I1: Liczba NTO | J1: suma | K1: rbh | L1: srednia zadan/godz
A2: Osoba 1 | B2: 9 | C2: 10 | D2: 7 | E2: 3 | F2: 1 | G2: 2 | H2: 18 | I2: 6 | J2: =SUM(B2:I2) -> 56 | K2: 8 | L2: =IFERROR(J2/K2,"") -> 7
A3: Osoba 2 | B3: 5 | C3: 12 | D3: 3 | E3: 8 | F3: 2 | G3: 6 | H3: 13 | I3: 3 | J3: =SUM(B3:I3) -> 52 | K3: 8 | L3: =IFERROR(J3/K3,"") -> 6.5
A4: Osoba 3 | J4: =SUM(B4:I4) -> 0 | L4: =IFERROR(J4/K4,"")
A5: Osoba 4 | B5: 6 | C5: 14 | D5: 4 | E5: 6 | F5: 6 | G5: 3 | H5: 18 | I5: 2 | J5: =SUM(B5:I5) -> 59 | K5: 6 | L5: =IFERROR(J5/K5,"") -> 9.8333333
A6: Osoba 5 | B6: 5 | C6: 10 | D6: 2 | E6: 7 | F6: 7 | G6: 11 | H6: 3 | I6: 10 | J6: =SUM(B6:I6) -> 55 | K6: 8 | L6: =IFERROR(J6/K6,"") -> 6.875
A7: Osoba 6 | B7: 25 | C7: 4 | D7: 6 | E7: 7 | F7: 6 | G7: 8 | H7: 17 | I7: 8 | J7: =SUM(B7:I7) -> 81 | K7: 4 | L7: =IFERROR(J7/K7,"") -> 20.25
A8: Osoba 7 | B8: 7 | C8: 11 | D8: 10 | E8: 1 | F8: 5 | G8: 11 | H8: 5 | I8: 8 | J8: =SUM(B8:I8) -> 58 | K8: 8 | L8: =IFERROR(J8/K8,"") -> 7.25
A9: Osoba 8 | B9: 8 | C9: 10 | D9: 9 | E9: 5 | F9: 1 | G9: 7 | H9: 12 | I9: 3 | J9: =SUM(B9:I9) -> 55 | K9: 8 | L9: =IFERROR(J9/K9,"") -> 6.875
A10: Osoba 9 | B10: 15 | C10: 13 | D10: 9 | E10: 8 | F10: 4 | G10: 7 | H10: 15 | I10: 5 | J10: =SUM(B10:I10) -> 76 | K10: 8 | L10: =IFERROR(J10/K10,"") -> 9.5
A11: Osoba 10 | B11: 11 | C11: 6 | D11: 8 | E11: 4 | F11: 6 | G11: 5 | H11: 7 | I11: 3 | J11: =SUM(B11:I11) -> 50 | K11: 4 | L11: =IFERROR(J11/K11,"") -> 12.5
A12: Osoba 11 | B12: 6 | C12: 14 | D12: 3 | E12: 5 | F12: 3 | G12: 3 | H12: 17 | I12: 8 | J12: =SUM(B12:I12) -> 59 | K12: 8 | L12: =IFERROR(J12/K12,"") -> 7.375
A13: Osoba 12 | B13: 18 | C13: 9 | D13: 10 | E13: 8 | F13: 6 | G13: 11 | H13: 17 | I13: 6 | J13: =SUM(B13:I13) -> 85 | K13: 8 | L13: =IFERROR(J13/K13,"") -> 10.625
A14: Osoba 13 | B14: 13 | C14: 12 | D14: 2 | E14: 5 | F14: 6 | G14: 6 | H14: 3 | I14: 3 | J14: =SUM(B14:I14) -> 50 | K14: 6 | L14: =IFERROR(J14/K14,"") -> 8.3333333
A15: Osoba 14 | B15: 5 | C15: 15 | D15: 6 | E15: 4 | F15: 3 | G15: 2 | H15: 6 | I15: 8 | J15: =SUM(B15:I15) -> 49 | K15: 8 | L15: =IFERROR(J15/K15,"") -> 6.125
A16: Osoba 15 | B16: 25 | C16: 13 | D16: 7 | E16: 2 | F16: 4 | G16: 5 | H16: 18 | I16: 5 | J16: =SUM(B16:I16) -> 79 | K16: 8 | L16: =IFERROR(J16/K16,"") -> 9.875
... A20: Osoba 19 | B20: 17 | C20: 4 | D20: 6 | E20: 6 | F20: 5 | G20: 2 | H20: 14 | I20: 9 | J20: =SUM(B20:I20) -> 63 | K20: 8 | L20: =IFERROR(J20/K20,"") -> 7.875
A21: Osoba 20 | J21: =SUM(B21:I21) -> 0 | L21: =IFERROR(J21/K21,"")
A22: Osoba 21 | B22: 18 | C22: 15 | D22: 6 | E22: 8 | F22: 1 | G22: 5 | H22: 5 | I22: 7 | J22: =SUM(B22:I22) -> 65 | K22: 8 | L22: =IFERROR(J22/K22,"") -> 8.125

Sheet 06
A1: Osoba | B1: L.Telefonow | C1: L. maili DWS | D1: L.Maili NTO | E1: L.Maili Vouchery | F1: L.Maili MDA | G1: L.TODO | H1: L.Chat | I1: Liczba NTO | J1: suma | K1: rbh | L1: srednia zadan/godz
A2: Osoba 1 | B2: 15 | C2: 13 | D2: 4 | E2: 8 | F2: 3 | G2: 10 | H2: 19 | I2: 8 | J2: =SUM(B2:I2) -> 80 | K2: 4 | L2: =IFERROR(J2/K2,"") -> 20
A3: Osoba 2 | B3: 7 | C3: 15 | D3: 5 | E3: 8 | F3: 5 | G3: 10 | H3: 8 | I3: 9 | J3: =SUM(B3:I3) -> 67 | K3: 8 | L3: =IFERROR(J3/K3,"") -> 8.375
A4: Osoba 3 | B4: 17 | C4: 12 | D4: 5 | E4: 5 | F4: 3 | G4: 10 | H4: 19 | I4: 5 | J4: =SUM(B4:I4) -> 76 | K4: 4 | L4: =IFERROR(J4/K4,"") -> 19
A5: Osoba 4 | B5: 22 | C5: 4 | D5: 10 | E5: 1 | F5: 7 | G5: 2 | H5: 20 | I5: 1 | J5: =SUM(B5:I5) -> 67 | K5: 6 | L5: =IFERROR(J5/K5,"") -> 11.166667
A6: Osoba 5 | B6: 23 | C6: 4 | D6: 9 | E6: 2 | F6: 3 | G6: 3 | H6: 20 | I6: 8 | J6: =SUM(B6:I6) -> 72 | K6: 6 | L6: =IFERROR(J6/K6,"") -> 12
A7: Osoba 6 | B7: 17 | C7: 7 | D7: 5 | E7: 8 | F7: 8 | G7: 4 | H7: 13 | I7: 7 | J7: =SUM(B7:I7) -> 69 | K7: 4 | L7: =IFERROR(J7/K7,"") -> 17.25
A8: Osoba 7 | B8: 8 | C8: 6 | D8: 8 | E8: 1 | F8: 5 | G8: 4 | H8: 3 | I8: 1 | J8: =SUM(B8:I8) -> 36 | K8: 8 | L8: =IFERROR(J8/K8,"") -> 4.5
A9: Osoba 8 | B9: 5 | C9: 13 | D9: 6 | E9: 6 | F9: 6 | G9: 5 | H9: 18 | I9: 2 | J9: =SUM(B9:I9) -> 61 | K9: 4 | L9: =IFERROR(J9/K9,"") -> 15.25
A10: Osoba 9 | B10: 8 | C10: 11 | D10: 6 | E10: 4 | F10: 7 | G10: 2 | H10: 15 | I10: 7 | J10: =SUM(B10:I10) -> 60 | K10: 8 | L10: =IFERROR(J10/K10,"") -> 7.5
A11: Osoba 10 | B11: 25 | C11: 11 | D11: 5 | E11: 4 | F11: 3 | G11: 5 | H11: 14 | I11: 3 | J11: =SUM(B11:I11) -> 70 | K11: 8 | L11: =IFERROR(J11/K11,"") -> 8.75
A12: Osoba 11 | B12: 11 | C12: 6 | D12: 5 | E12: 2 | F12: 3 | G12: 5 | H12: 7 | I12: 2 | J12: =SUM(B12:I12) -> 41 | K12: 8 | L12: =IFERROR(J12/K12,"") -> 5.125
A13: Osoba 12 | B13: 18 | C13: 9 | D13: 10 | E13: 3 | F13: 4 | G13: 8 | H13: 3 | I13: 2 | J13: =SUM(B13:I13) -> 57 | K13: 8 | L13: =IFERROR(J13/K13,"") -> 7.125
A14: Osoba 13 | B14: 16 | C14: 8 | D14: 3 | E14: 6 | F14: 4 | G14: 3 | H14: 18 | I14: 2 | J14: =SUM(B14:I14) -> 60 | K14: 8 | L14: =IFERROR(J14/K14,"") -> 7.5
A15: Osoba 14 | J15: =SUM(B15:I15) -> 0 | L15: =IFERROR(J15/K15,"")
A16: Osoba 15 | B16: 21 | C16: 12 | D16: 9 | E16: 3 | F16: 4 | G16: 4 | H16: 6 | I16: 4 | J16: =SUM(B16:I16) -> 63 | K16: 8 | L16: =IFERROR(J16/K16,"") -> 7.875
A17: Osoba 16 | B17: 14 | C17: 13 | D17: 3 | E17: 1 | F17: 3 | G17: 12 | H17: 17 | I17: 2 | J17: =SUM(B17:I17) -> 65 | K17: 8 | L17: =IFERROR(J17/K17,"") -> 8.125
A18: Osoba 17 | B18: 19 | C18: 9 | D18: 10 | E18: 6 | F18: 7 | G18: 5 | H18: 14 | I18: 1 | J18: =SUM(B18:I18) -> 71 | K18: 8 | L18: =IFERROR(J18/K18,"") -> 8.875
A19: Osoba 18 | B19: 10 | C19: 9 | D19: 9 | E19: 6 | F19: 6 | G19: 8 | H19: 9 | I19: 10 | J19: =SUM(B19:I19) -> 67 | K19: 8 | L19: =IFERROR(J19/K19,"") -> 8.375
A20: Osoba 19 | B20: 5 | C20: 8 | D20: 3 | E20: 7 | F20: 4 | G20: 10 | H20: 13 | I20: 5 | J20: =SUM(B20:I20) -> 55 | K20: 8 | L20: =IFERROR(J20/K20,"") -> 6.875
A21: Osoba 20 | B21: 10 | C21: 9 | D21: 4 | E21: 6 | F21: 6 | G21: 8 | H21: 8 | I21: 7 | J21: =SUM(B21:I21) -> 58 | K21: 8 | L21: =IFERROR(J21/K21,"") -> 7.25
A22: Osoba 21 | B22: 7 | C22: 15 | D22: 7 | E22: 5 | F22: 8 | G22: 3 | H22: 3 | I22: 6 | J22: =SUM(B22:I22) -> 54 | K22: 8 | L22: =IFERROR(J22/K22,"") -> 6.75

Sheet 07
A1: Osoba | B1: L.Telefonow | C1: L. maili DWS | D1: L.Maili NTO | E1: L.Maili Vouchery | F1: L.Maili MDA | G1: L.TODO | H1: L.Chat | I1: Liczba NTO | J1: suma | K1: rbh | L1: srednia zadan/godz
A2: Osoba 1 | B2: 14 | C2: 8 | D2: 5 | E2: 7 | F2: 3 | G2: 10 | H2: 5 | I2: 7 | J2: =SUM(B2:I2) -> 59 | K2: 4 | L2: =IFERROR(J2/K2,"") -> 14.75
A3: Osoba 2 | B3: 8 | C3: 15 | D3: 8 | E3: 1 | F3: 2 | G3: 11 | H3: 6 | I3: 4 | J3: =SUM(B3:I3) -> 55 | K3: 8 | L3: =IFERROR(J3/K3,"") -> 6.875
A4: Osoba 3 | B4: 21 | C4: 3 | D4: 5 | E4: 7 | F4: 1 | G4: 3 | H4: 11 | I4: 5 | J4: =SUM(B4:I4) -> 56 | K4: 8 | L4: =IFERROR(J4/K4,"") -> 7
A5: Osoba 4 | B5: 22 | C5: 11 | D5: 10 | E5: 7 | F5: 2 | G5: 12 | H5: 17 | I5: 2 | J5: =SUM(B5:I5) -> 83 | K5: 8 | L5: =IFERROR(J5/K5,"") -> 10.375
A6: Osoba 5 | B6: 10 | C6: 9 | D6: 9 | E6: 3 | F6: 8 | G6: 10 | H6: 4 | I6: 7 | J6: =SUM(B6:I6) -> 60 | K6: 4 | L6: =IFERROR(J6/K6,"") -> 15
A7: Osoba 6 | B7: 21 | C7: 9 | D7: 6 | E7: 6 | F7: 5 | G7: 9 | H7: 11 | I7: 9 | J7: =SUM(B7:I7) -> 76 | K7: 8 | L7: =IFERROR(J7/K7,"") -> 9.5
A8: Osoba 7 | B8: 14 | C8: 3 | D8: 2 | E8: 4 | F8: 1 | G8: 12 | H8: 8 | I8: 7 | J8: =SUM(B8:I8) -> 51 | K8: 6 | L8: =IFERROR(J8/K8,"") -> 8.5
A9: Osoba 8 | J9: =SUM(B9:I9) -> 0 | L9: =IFERROR(J9/K9,"")
A10: Osoba 9 | B10: 17 | C10: 3 | D10: 7 | E10: 2 | F10: 4 | G10: 8 | H10: 18 | I10: 5 | J10: =SUM(B10:I10) -> 64 | K10: 8 | L10: =IFERROR(J10/K10,"") -> 8
A11: Osoba 10 | J11: =SUM(B11:I11) -> 0 | L11: =IFERROR(J11/K11,"")
A12: Osoba 11 | B12: 19 | C12: 5 | D12: 5 | E12: 2 | F12: 1 | G12: 11 | H12: 16 | I12: 8 | J12: =SUM(B12:I12) -> 67 | K12: 8 | L12: =IFERROR(J12/K12,"") -> 8.375
A13: Osoba 12 | B13: 6 | C13: 8 | D13: 10 | E13: 3 | F13: 2 | G13: 7 | H13: 17 | I13: 3 | J13: =SUM(B13:I13) -> 56 | K13: 6 | L13: =IFERROR(J13/K13,"") -> 9.3333333
A14: Osoba 13 | B14: 13 | C14: 13 | D14: 8 | E14: 6 | F14: 3 | G14: 6 | H14: 7 | I14: 4 | J14: =SUM(B14:I14) -> 60 | K14: 4 | L14: =IFERROR(J14/K14,"") -> 15
A15: Osoba 14 | B15: 14 | C15: 15 | D15: 10 | E15: 6 | F15: 5 | G15: 6 | H15: 9 | I15: 5 | J15: =SUM(B15:I15) -> 70 | K15: 8 | L15: =IFERROR(J15/K15,"") -> 8.75
A16: Osoba 15 | B16: 12 | C16: 11 | D16: 5 | E16: 1 | F16: 1 | G16: 2 | H16: 11 | I16: 5 | J16: =SUM(B16:I16) -> 48 | K16: 6 | L16: =IFERROR(J16/K16,"") -> 8
A17: Osoba 16 | J17: =SUM(B17:I17) -> 0 | L17: =IFERROR(J17/K17,"")
A18: Osoba 17 | J18: =SUM(B18:I18) -> 0 | L18: =IFERROR(J18/K18,"")
A19: Osoba 18 | B19: 13 | C19: 4 | D19: 3 | E19: 3 | F19: 4 | G19: 12 | H19: 14 | I19: 8 | J19: =SUM(B19:I19) -> 61 | K19: 4 | L19: =IFERROR(J19/K19,"") -> 15.25
A20: Osoba 19 | B20: 15 | C20: 8 | D20: 9 | E20: 3 | F20: 2 | G20: 3 | H20: 17 | I20: 10 | J20: =SUM(B20:I20) -> 67 | K20: 8 | L20: =IFERROR(J20/K20,"") -> 8.375
A21: Osoba 20 | B21: 13 | C21: 9 | D21: 4 | E21: 6 | F21: 3 | G21: 12 | H21: 13 | I21: 5 | J21: =SUM(B21:I21) -> 65 | K21: 8 | L21: =IFERROR(J21/K21,"") -> 8.125
A22: Osoba 21 | B22: 16 | C22: 12 | D22: 3 | E22: 8 | F22: 6 | G22: 3 | H22: 20 | I22: 2 | J22: =SUM(B22:I22) -> 70 | K22: 6 | L22: =IFERROR(J22/K22,"") -> 11.666667

Sheet 08
A1: Osoba | B1: L.Telefonow | C1: L. maili DWS | D1: L.Maili NTO | E1: L.Maili Vouchery | F1: L.Maili MDA | G1: L.TODO | H1: L.Chat | I1: Liczba NTO | J1: suma | K1: rbh | L1: srednia zadan/godz
A2: Osoba 1 | B2: 20 | C2: 13 | D2: 9 | E2: 5 | F2: 1 | G2: 3 | H2: 12 | I2: 4 | J2: =SUM(B2:I2) -> 67 | K2: 8 | L2: =IFERROR(J2/K2,"") -> 8.375
A3: Osoba 2 | B3: 20 | C3: 14 | D3: 7 | E3: 5 | F3: 3 | G3: 5 | H3: 14 | I3: 6 | J3: =SUM(B3:I3) -> 74 | K3: 8 | L3: =IFERROR(J3/K3,"") -> 9.25
A4: Osoba 3 | B4: 15 | C4: 14 | D4: 9 | E4: 5 | F4: 8 | G4: 10 | H4: 12 | I4: 8 | J4: =SUM(B4:I4) -> 81 | K4: 8 | L4: =IFERROR(J4/K4,"") -> 10.125
A5: Osoba 4 | B5: 21 | C5: 6 | D5: 3 | E5: 6 | F5: 6 | G5: 2 | H5: 14 | I5: 7 | J5: =SUM(B5:I5) -> 65 | K5: 6 | L5: =IFERROR(J5/K5,"") -> 10.833333
A6: Osoba 5 | B6: 23 | C6: 8 | D6: 8 | E6: 3 | F6: 3 | G6: 4 | H6: 5 | I6: 8 | J6: =SUM(B6:I6) -> 62 | K6: 8 | L6: =IFERROR(J6/K6,"") -> 7.75
A7: Osoba 6 | B7: 12 | C7: 11 | D7: 2 | E7: 3 | F7: 5 | G7: 2 | H7: 16 | I7: 2 | J7: =SUM(B7:I7) -> 53 | K7: 8 | L7: =IFERROR(J7/K7,"") -> 6.625
A8: Osoba 7 | B8: 7 | C8: 8 | D8: 3 | E8: 5 | F8: 2 | G8: 7 | H8: 5 | I8: 1 | J8: =SUM(B8:I8) -> 38 | K8: 8 | L8: =IFERROR(J8/K8,"") -> 4.75
A9: Osoba 8 | B9: 25 | C9: 9 | D9: 5 | E9: 4 | F9: 8 | G9: 10 | H9: 13 | I9: 8 | J9: =SUM(B9:I9) -> 82 | K9: 6 | L9: =IFERROR(J9/K9,"") -> 13.666667
A10: Osoba 9 | B10: 15 | C10: 13 | D10: 4 | E10: 8 | F10: 8 | G10: 10 | H10: 5 | I10: 10 | J10: =SUM(B10:I10) -> 73 | K10: 8 | L10: =IFERROR(J10/K10,"") -> 9.125
A11: Osoba 10 | B11: 16 | C11: 3 | D11: 8 | E11: 2 | F11: 8 | G11: 10 | H11: 3 | I11: 9 | J11: =SUM(B11:I11) -> 59 | K11: 8 | L11: =IFERROR(J11/K11,"") -> 7.375
A12: Osoba 11 | B12: 8 | C12: 9 | D12: 8 | E12: 3 | F12: 4 | G12: 4 | H12: 15 | I12: 3 | J12: =SUM(B12:I12) -> 54 | K12: 8 | L12: =IFERROR(J12/K12,"") -> 6.75
A13: Osoba 12 | B13: 18 | C13: 11 | D13: 6 | E13: 5 | F13: 1 | G13: 9 | H13: 12 | I13: 2 | J13: =SUM(B13:I13) -> 64 | K13: 8 | L13: =IFERROR(J13/K13,"") -> 8
... A21: Osoba 20 | B21: 21 | C21: 4 | D21: 9 | E21: 8 | F21: 2 | G21: 11 | H21: 20 | I21: 9 | J21: =SUM(B21:I21) -> 84 | K21: 8 | L21: =IFERROR(J21/K21,"") -> 10.5
A22: Osoba 21 | J22: =SUM(B22:I22) -> 0 | L22: =IFERROR(J22/K22,"")

Sheet 09
A1: Osoba | B1: L.Telefonow | C1: L. maili DWS | D1: L.Maili NTO | E1: L.Maili Vouchery | F1: L.Maili MDA | G1: L.TODO | H1: L.Chat | I1: Liczba NTO | J1: suma | K1: rbh | L1: srednia zadan/godz
A2: Osoba 1 | J2: =SUM(B2:I2) -> 0 | L2: =IFERROR(J2/K2,"")
A3: Osoba 2 | J3: =SUM(B3:I3) -> 0 | L3: =IFERROR(J3/K3,"")
A4: Osoba 3 | J4: =SUM(B4:I4) -> 0 | L4: =IFERROR(J4/K4,"")
A5: Osoba 4 | J5: =SUM(B5:I5) -> 0 | L5: =IFERROR(J5/K5,"")
A6: Osoba 5 | J6: =SUM(B6:I6) -> 0 | L6: =IFERROR(J6/K6,"")
A7: Osoba 6 | J7: =SUM(B7:I7) -> 0 | L7: =IFERROR(J7/K7,"")
A8: Osoba 7 | J8: =SUM(B8:I8) -> 0 | L8: =IFERROR(J8/K8,"")
A9: Osoba 8 | J9: =SUM(B9:I9) -> 0 | L9: =IFERROR(J9/K9,"")
A10: Osoba 9 | J10: =SUM(B10:I10) -> 0 | L10: =IFERROR(J10/K10,"")
A11: Osoba 10 | J11: =SUM(B11:I11) -> 0 | L11: =IFERROR(J11/K11,"")
A12: Osoba 11 | J12: =SUM(B12:I12) -> 0 | L12: =IFERROR(J12/K12,"")
A13: Osoba 12 | J13: =SUM(B13:I13) -> 0 | L13: =IFERROR(J13/K13,"")
... A22: Osoba 21 | J22: =SUM(B22:I22) -> 0 | L22: =IFERROR(J22/K22,"")

Sheet 10
A1: Osoba | B1: L.Telefonow | C1: L. maili DWS | D1: L.Maili NTO | E1: L.Maili Vouchery | F1: L.Maili MDA | G1: L.TODO | H1: L.Chat | I1: Liczba NTO | J1: suma | K1: rbh | L1: srednia zadan/godz
A2: Osoba 1 | J2: =SUM(B2:I2) -> 0 | L2: =IFERROR(J2/K2,"")
A3: Osoba 2 | J3: =SUM(B3:I3) -> 0 | L3: =IFERROR(J3/K3,"")
A4: Osoba 3 | J4: =SUM(B4:I4) -> 0 | L4: =IFERROR(J4/K4,"")
A5: Osoba 4 | J5: =SUM(B5:I5) -> 0 | L5: =IFERROR(J5/K5,"")
A6: Osoba 5 | J6: =SUM(B6:I6) -> 0 | L6: =IFERROR(J6/K6,"")
A7: Osoba 6 | J7: =SUM(B7:I7) -> 0 | L7: =IFERROR(J7/K7,"")
A8: Osoba 7 | J8: =SUM(B8:I8) -> 0 | L8: =IFERROR(J8/K8,"")
A9: Osoba 8 | J9: =SUM(B9:I9) -> 0 | L9: =IFERROR(J9/K9,"")
A10: Osoba 9 | J10: =SUM(B10:I10) -> 0 | L10: =IFERROR(J10/K10,"")
A11: Osoba 10 | J11: =SUM(B11:I11) -> 0 | L11: =IFERROR(J11/K11,"")
A12: Osoba 11 | J12: =SUM(B12:I12) -> 0 | L12: =IFERROR(J12/K12,"")
A13: Osoba 12 | J13: =SUM(B13:I13) -> 0 | L13: =IFERROR(J13/K13,"")
... A22: Osoba 21 | J22: =SUM(B22:I22) -> 0 | L22: =IFERROR(J22/K22,"")

Sheet 11
A1: Osoba | B1: L.Telefonow | C1: L. maili DWS | D1: L.Maili NTO | E1: L.Maili Vouchery | F1: L.Maili MDA | G1: L.TODO | H1: L.Chat | I1: Liczba NTO | J1: suma | K1: rbh | L1: srednia zadan/godz
A2: Osoba 1 | B2: 11 | C2: 13 | D2: 3 | E2: 8 | F2: 4 | G2: 2 | H2: 20 | I2: 7 | J2: =SUM(B2:I2) -> 68 | K2: 4 | L2: =IFERROR(J2/K2,"") -> 17
A3: Osoba 2 | B3: 14 | C3: 8 | D3: 6 | E3: 7 | F3: 2 | G3: 10 | H3: 12 | I3: 8 | J3: =SUM(B3:I3) -> 67 | K3: 8 | L3: =IFERROR(J3/K3,"") -> 8.375
A4: Osoba 3 | B4: 9 | C4: 4 | D4: 8 | E4: 8 | F4: 2 | G4: 12 | H4: 17 | I4: 1 | J4: =SUM(B4:I4) -> 61 | K4: 6 | L4: =IFERROR(J4/K4,"") -> 10.166667
A5: Osoba 4 | B5: 20 | C5: 6 | D5: 6 | E5: 2 | F5: 8 | G5: 2 | H5: 9 | I5: 10 | J5: =SUM(B5:I5) -> 63 | K5: 8 | L5: =IFERROR(J5/K5,"") -> 7.875
A6: Osoba 5 | B6: 17 | C6: 11 | D6: 6 | E6: 6 | F6: 7 | G6: 10 | H6: 5 | I6: 5 | J6: =SUM(B6:I6) -> 67 | K6: 8 | L6: =IFERROR(J6/K6,"") -> 8.375
A7: Osoba 6 | B7: 8 | C7: 8 | D7: 6 | E7: 5 | F7: 8 | G7: 12 | H7: 13 | I7: 8 | J7: =SUM(B7:I7) -> 68 | K7: 6 | L7: =IFERROR(J7/K7,"") -> 11.333333
A8: Osoba 7 | B8: 9 | C8: 12 | D8: 3 | E8: 3 | F8: 3 | G8: 4 | H8: 9 | I8: 7 | J8: =SUM(B8:I8) -> 50 | K8: 8 | L8: =IFERROR(J8/K8,"") -> 6.25
A9: Osoba 8 | B9: 23 | C9: 14 | D9: 3 | E9: 2 | F9: 4 | G9: 2 | H9: 8 | I9: 2 | J9: =SUM(B9:I9) -> 58 | K9: 6 | L9: =IFERROR(J9/K9,"") -> 9.6666667
A10: Osoba 9 | B10: 7 | C10: 8 | D10: 8 | E10: 3 | F10: 4 | G10: 4 | H10: 15 | I10: 8 | J10: =SUM(B10:I10) -> 57 | K10: 8 | L10: =IFERROR(J10/K10,"") -> 7.125
A11: Osoba 10 | B11: 24 | C11: 3 | D11: 8 | E11: 6 | F11: 4 | G11: 12 | H11: 19 | I11: 1 | J11: =SUM(B11:I11) -> 77 | K11: 8 | L11: =IFERROR(J11/K11,"") -> 9.625
A12: Osoba 11 | B12: 15 | C12: 7 | D12: 9 | E12: 2 | F12: 7 | G12: 5 | H12: 19 | I12: 6 | J12: =SUM(B12:I12) -> 70 | K12: 8 | L12: =IFERROR(J12/K12,"") -> 8.75
A13: Osoba 12 | B13: 24 | C13: 14 | D13: 4 | E13: 5 | F13: 5 | G13: 10 | H13: 10 | I13: 6 | J13: =SUM(B13:I13) -> 78 | K13: 8 | L13: =IFERROR(J13/K13,"") -> 9.75
... A22: Osoba 21 | B22: 8 | C22: 11 | D22: 7 | E22: 7 | F22: 7 | G22: 2 | H22: 13 | I22: 1 | J22: =SUM(B22:I22) -> 56 | K22: 8 | L22: =IFERROR(J22/K22,"") -> 7

Sheet 12
A1: Osoba | B1: L.Telefonow | C1: L. maili DWS | D1: L.Maili NTO | E1: L.Maili Vouchery | F1: L.Maili MDA | G1: L.TODO | H1: L.Chat | I1: Liczba NTO | J1: suma | K1: rbh | L1: srednia zadan/godz
A2: Osoba 1 | B2: 18 | C2: 14 | D2: 8 | E2: 6 | F2: 5 | G2: 11 | H2: 5 | I2: 4 | J2: =SUM(B2:I2) -> 71 | K2: 8 | L2: =IFERROR(J2/K2,"") -> 8.875
A3: Osoba 2 | B3: 12 | C3: 11 | D3: 8 | E3: 1 | F3: 8 | G3: 3 | H3: 19 | I3: 4 | J3: =SUM(B3:I3) -> 66 | K3: 8 | L3: =IFERROR(J3/K3,"") -> 8.25
A4: Osoba 3 | B4: 12 | C4: 4 | D4: 7 | E4: 7 | F4: 3 | G4: 5 | H4: 16 | I4: 10 | J4: =SUM(B4:I4) -> 64 | K4: 8 | L4: =IFERROR(J4/K4,"") -> 8
A5: Osoba 4 | B5: 8 | C5: 11 | D5: 4 | E5: 2 | F5: 8 | G5: 2 | H5: 12 | I5: 4 | J5: =SUM(B5:I5) -> 51 | K5: 8 | L5: =IFERROR(J5/K5,"") -> 6.375
A6: Osoba 5 | J6: =SUM(B6:I6) -> 0 | L6: =IFERROR(J6/K6,"")
A7: Osoba 6 | B7: 19 | C7: 10 | D7: 10 | E7: 7 | F7: 3 | G7: 7 | H7: 10 | I7: 1 | J7: =SUM(B7:I7) -> 67 | K7: 8 | L7: =IFERROR(J7/K7,"") -> 8.375
A8: Osoba 7 | J8: =SUM(B8:I8) -> 0 | L8: =IFERROR(J8/K8,"")
A9: Osoba 8 | B9: 14 | C9: 8 | D9: 9 | E9: 3 | F9: 8 | G9: 5 | H9: 9 | I9: 5 | J9: =SUM(B9:I9) -> 61 | K9: 8 | L9: =IFERROR(J9/K9,"") -> 7.625
A10: Osoba 9 | B10: 16 | C10: 10 | D10: 2 | E10: 3 | F10: 4 | G10: 10 | H10: 10 | I10: 4 | J10: =SUM(B10:I10) -> 59 | K10: 8 | L10: =IFERROR(J10/K10,"") -> 7.375
A11: Osoba 10 | B11: 14 | C11: 14 | D11: 7 | E11: 5 | F11: 7 | G11: 4 | H11: 13 | I11: 8 | J11: =SUM(B11:I11) -> 72 | K11: 6 | L11: =IFERROR(J11/K11,"") -> 12
A12: Osoba 11 | J12: =SUM(B12:I12) -> 0 | L12: =IFERROR(J12/K12,"")
A13: Osoba 12 | B13: 14 | C13: 4 | D13: 5 | E13: 5 | F13: 3 | G13: 5 | H13: 19 | I13: 5 | J13: =SUM(B13:I13) -> 60 | K13: 8 | L13: =IFERROR(J13/K13,"") -> 7.5
A14: Osoba 13 | B14: 21 | C14: 4 | D14: 10 | E14: 4 | F14: 5 | G14: 4 | H14: 10 | I14: 5 | J14: =SUM(B14:I14) -> 63 | K14: 8 | L14: =IFERROR(J14/K14,"") -> 7.875
A15: Osoba 14 | B15: 7 | C15: 10 | D15: 3 | E15: 8 | F15: 2 | G15: 10 | H15: 4 | I15: 1 | J15: =SUM(B15:I15) -> 45 | K15: 8 | L15: =IFERROR(J15/K15,"") -> 5.625
A16: Osoba 15 | B16: 18 | C16: 15 | D16: 3 | E16: 3 | F16: 5 | G16: 5 | H16: 10 | I16: 3 | J16: =SUM(B16:I16) -> 62 | K16: 8 | L16: =IFERROR(J16/K16,"") -> 7.75
A17: Osoba 16 | B17: 5 | C17: 5 | D17: 4 | E17: 1 | F17: 8 | G17: 11 | H17: 15 | I17: 1 | J17: =SUM(B17:I17) -> 50 | K17: 4 | L17: =IFERROR(J17/K17,"") -> 12.5
A18: Osoba 17 | J18: =SUM(B18:I18) -> 0 | L18: =IFERROR(J18/K18,"")
A19: Osoba 18 | J19: =SUM(B19:I19) -> 0 | L19: =IFERROR(J19/K19,"")
A20: Osoba 19 | B20: 16 | C20: 8 | D20: 9 | E20: 1 | F20: 5 | G20: 10 | H20: 19 | I20: 9 | J20: =SUM(B20:I20) -> 77 | K20: 8 | L20: =IFERROR(J20/K20,"") -> 9.625
A21: Osoba 20 | B21: 10 | C21: 4 | D21: 8 | E21: 4 | F21: 8 | G21: 10 | H21: 11 | I21: 4 | J21: =SUM(B21:I21) -> 59 | K21: 8 | L21: =IFERROR(J21/K21,"") -> 7.375
A22: Osoba 21 | B22: 12 | C22: 12 | D22: 9 | E22: 5 | F22: 1 | G22: 5 | H22: 4 | I22: 10 | J22: =SUM(B22:I22) -> 58 | K22: 4 | L22: =IFERROR(J22/K22,"") -> 14.5

Sheet 13
A1: Osoba | B1: L.Telefonow | C1: L. maili DWS | D1: L.Maili NTO | E1: L.Maili Vouchery | F1: L.Maili MDA | G1: L.TODO | H1: L.Chat | I1: Liczba NTO | J1: suma | K1: rbh | L1: srednia zadan/godz
A2: Osoba 1 | B2: 10 | C2: 8 | D2: 4 | E2: 1 | F2: 8 | G2: 8 | H2: 19 | I2: 8 | J2: =SUM(B2:I2) -> 66 | K2: 8 | L2: =IFERROR(J2/K2,"") -> 8.25
A3: Osoba 2 | B3: 5 | C3: 4 | D3: 3 | E3: 3 | F3: 4 | G3: 11 | H3: 7 | I3: 1 | J3: =SUM(B3:I3) -> 38 | K3: 8 | L3: =IFERROR(J3/K3,"") -> 4.75
A4: Osoba 3 | B4: 15 | C4: 12 | D4: 10 | E4: 5 | F4: 8 | G4: 3 | H4: 19 | I4: 3 | J4: =SUM(B4:I4) -> 75 | K4: 6 | L4: =IFERROR(J4/K4,"") -> 12.5
A5: Osoba 4 | B5: 10 | C5: 10 | D5: 9 | E5: 1 | F5: 6 | G5: 8 | H5: 17 | I5: 6 | J5: =SUM(B5:I5) -> 67 | K5: 8 | L5: =IFERROR(J5/K5,"") -> 8.375
A6: Osoba 5 | B6: 6 | C6: 5 | D6: 9 | E6: 3 | F6: 3 | G6: 9 | H6: 19 | I6: 1 | J6: =SUM(B6:I6) -> 55 | K6: 8 | L6: =IFERROR(J6/K6,"") -> 6.875
A7: Osoba 6 | B7: 21 | C7: 5 | D7: 3 | E7: 7 | F7: 5 | G7: 9 | H7: 16 | I7: 2 | J7: =SUM(B7:I7) -> 68 | K7: 8 | L7: =IFERROR(J7/K7,"") -> 8.5
